Workbook

Sheet 💰 Transaction ขาย
A1: วันที่ | B1: ชื่อสินค้า | C1: ราคา | D1: หน่วยนับ | E1: จำนวนที่ขาย | F1: มูลค่ารวม | G1: ต้นทุนเฉลี่ยรวม | H1: กำไรขั้นต้น | I1: %กำไรขั้นต้น | J1: ปีเดือน | K1: กลุ่มสินค้า | L1: Date | M1: หมายเหตุ
A2: 45437 | B2: 831 สีโอรส | D2: โล | F2: =IF(LEN(B2)>0,C2*E2,"") -> 0 | G2: =IF(LEN(B2)>0,vlookup(B2,'📊 รายงานสินค้าคงเหลือ'!A:G,6,false)*E2,) -> 0 | H2: =IF(LEN(B2)>0,F2-G2,) -> 0 | I2: =IF(LEN(B2)>0,H2/F2,) -> #DIV/0! | J2: =IF(A2<>"",YEAR(A2)&"-"&MONTH(A2),"") -> 2024-5 | K2: =IFERROR(IF(A2<>"",VLOOKUP(B2,'📦 ชื่อสินค้า'!A:F,6,false),""),) -> รุ่นสีอ่อน | L2: =IF(A2<>"",A2,) -> 45437
A3: 45411 | B3: 881 เปลือกไม้ รุ่นหยัก | C3: 250 | D3: โล | E3: 1 | F3: =IF(LEN(B3)>0,C3*E3,"") -> 250 | G3: =IF(LEN(B3)>0,vlookup(B3,'📊 รายงานสินค้าคงเหลือ'!A:G,6,false)*E3,) -> #VALUE! | H3: =IF(LEN(B3)>0,F3-G3,) -> #VALUE! | I3: =IF(LEN(B3)>0,H3/F3,) -> #VALUE! | J3: =IF(A3<>"",YEAR(A3)&"-"&MONTH(A3),"") -> 2024-4 | K3: =IFERROR(IF(A3<>"",VLOOKUP(B3,'📦 ชื่อสินค้า'!A:F,6,false),""),) -> รุ่นหยัก | L3: =IF(A3<>"",A3,) -> 45411
A4: 45426 | B4: 881 เปลือกไม้ | C4: 150 | D4: โล | E4: 20 | F4: =IF(LEN(B4)>0,C4*E4,"") -> 3000 | G4: =IF(LEN(B4)>0,vlookup(B4,'📊 รายงานสินค้าคงเหลือ'!A:G,6,false)*E4,) -> 1600 | H4: =IF(LEN(B4)>0,F4-G4,) -> 1400 | I4: =IF(LEN(B4)>0,H4/F4,) -> 0.46666667 | J4: =IF(A4<>"",YEAR(A4)&"-"&MONTH(A4),"") -> 2024-5 | K4: =IFERROR(IF(A4<>"",VLOOKUP(B4,'📦 ชื่อสินค้า'!A:F,6,false),""),) -> รุ่นสีอ่อน | L4: =IF(A4<>"",A4,) -> 45426
A5: 45430 | B5: 521 ครีม | C5: 150 | D5: โล | E5: 3 | F5: =IF(LEN(B5)>0,C5*E5,"") -> 450 | G5: =IF(LEN(B5)>0,vlookup(B5,'📊 รายงานสินค้าคงเหลือ'!A:G,6,false)*E5,) -> 240 | H5: =IF(LEN(B5)>0,F5-G5,) -> 210 | I5: =IF(LEN(B5)>0,H5/F5,) -> 0.46666667 | J5: =IF(A5<>"",YEAR(A5)&"-"&MONTH(A5),"") -> 2024-5 | K5: =IFERROR(IF(A5<>"",VLOOKUP(B5,'📦 ชื่อสินค้า'!A:F,6,false),""),) -> รุ่นสีอ่อน | L5: =IF(A5<>"",A5,) -> 45430
A6: 45430 | B6: 831 สีโอรส | C6: 150 | D6: โล | E6: 3 | F6: =IF(LEN(B6)>0,C6*E6,"") -> 450 | G6: =IF(LEN(B6)>0,vlookup(B6,'📊 รายงานสินค้าคงเหลือ'!A:G,6,false)*E6,) -> 240 | H6: =IF(LEN(B6)>0,F6-G6,) -> 210 | I6: =IF(LEN(B6)>0,H6/F6,) -> 0.46666667 | J6: =IF(A6<>"",YEAR(A6)&"-"&MONTH(A6),"") -> 2024-5 | K6: =IFERROR(IF(A6<>"",VLOOKUP(B6,'📦 ชื่อสินค้า'!A:F,6,false),""),) -> รุ่นสีอ่อน | L6: =IF(A6<>"",A6,) -> 45430
A7: 45430 | B7: 853 ชมพูพาสเทล | C7: 150 | D7: โล | E7: 1 | F7: =IF(LEN(B7)>0,C7*E7,"") -> 150 | G7: =IF(LEN(B7)>0,vlookup(B7,'📊 รายงานสินค้าคงเหลือ'!A:G,6,false)*E7,) -> #VALUE! | H7: =IF(LEN(B7)>0,F7-G7,) -> #VALUE! | I7: =IF(LEN(B7)>0,H7/F7,) -> #VALUE! | J7: =IF(A7<>"",YEAR(A7)&"-"&MONTH(A7),"") -> 2024-5 | K7: =IFERROR(IF(A7<>"",VLOOKUP(B7,'📦 ชื่อสินค้า'!A:F,6,false),""),) -> รุ่นสีอ่อน | L7: =IF(A7<>"",A7,) -> 45430
A8: 45430 | B8: 860 ม่วงอ่อน | C8: 150 | D8: โล | E8: 2 | F8: =IF(LEN(B8)>0,C8*E8,"") -> 300 | G8: =IF(LEN(B8)>0,vlookup(B8,'📊 รายงานสินค้าคงเหลือ'!A:G,6,false)*E8,) -> 160 | H8: =IF(LEN(B8)>0,F8-G8,) -> 140 | I8: =IF(LEN(B8)>0,H8/F8,) -> 0.46666667 | J8: =IF(A8<>"",YEAR(A8)&"-"&MONTH(A8),"") -> 2024-5 | K8: =IFERROR(IF(A8<>"",VLOOKUP(B8,'📦 ชื่อสินค้า'!A:F,6,false),""),) -> รุ่นสีอ่อน | L8: =IF(A8<>"",A8,) -> 45430
A9: 45430 | B9: 862 ฟ้า PT อ่อน | C9: 150 | D9: โล | E9: 4 | F9: =IF(LEN(B9)>0,C9*E9,"") -> 600 | G9: =IF(LEN(B9)>0,vlookup(B9,'📊 รายงานสินค้าคงเหลือ'!A:G,6,false)*E9,) -> #VALUE! | H9: =IF(LEN(B9)>0,F9-G9,) -> #VALUE! | I9: =IF(LEN(B9)>0,H9/F9,) -> #VALUE! | J9: =IF(A9<>"",YEAR(A9)&"-"&MONTH(A9),"") -> 2024-5 | K9: =IFERROR(IF(A9<>"",VLOOKUP(B9,'📦 ชื่อสินค้า'!A:F,6,false),""),) -> รุ่นสีอ่อน | L9: =IF(A9<>"",A9,) -> 45430
A10: 45430 | B10: 510 ขาวธรรมชาติ | C10: 150 | D10: โล | E10: 20 | F10: =IF(LEN(B10)>0,C10*E10,"") -> 3000 | G10: =IF(LEN(B10)>0,vlookup(B10,'📊 รายงานสินค้าคงเหลือ'!A:G,6,false)*E10,) -> 1687.9558 | H10: =IF(LEN(B10)>0,F10-G10,) -> 1312.0442 | I10: =IF(LEN(B10)>0,H10/F10,) -> 0.43734807 | J10: =IF(A10<>"",YEAR(A10)&"-"&MONTH(A10),"") -> 2024-5 | K10: =IFERROR(IF(A10<>"",VLOOKUP(B10,'📦 ชื่อสินค้า'!A:F,6,false),""),) -> รุ่นสีอ่อน | L10: =IF(A10<>"",A10,) -> 45430
A11: 45430 | B11: 521 ครีม | C11: 150 | D11: โล | E11: 10 | F11: =IF(LEN(B11)>0,C11*E11,"") -> 1500 | G11: =IF(LEN(B11)>0,vlookup(B11,'📊 รายงานสินค้าคงเหลือ'!A:G,6,false)*E11,) -> 800 | H11: =IF(LEN(B11)>0,F11-G11,) -> 700 | I11: =IF(LEN(B11)>0,H11/F11,) -> 0.46666667 | J11: =IF(A11<>"",YEAR(A11)&"-"&MONTH(A11),"") -> 2024-5 | K11: =IFERROR(IF(A11<>"",VLOOKUP(B11,'📦 ชื่อสินค้า'!A:F,6,false),""),) -> รุ่นสีอ่อน | L11: =IF(A11<>"",A11,) -> 45430
A12: 45430 | B12: 522 เหลืองอ่อน | C12: 150 | D12: โล | E12: 10 | F12: =IF(LEN(B12)>0,C12*E12,"") -> 1500 | G12: =IF(LEN(B12)>0,vlookup(B12,'📊 รายงานสินค้าคงเหลือ'!A:G,6,false)*E12,) -> #VALUE! | H12: =IF(LEN(B12)>0,F12-G12,) -> #VALUE! | I12: =IF(LEN(B12)>0,H12/F12,) -> #VALUE! | J12: =IF(A12<>"",YEAR(A12)&"-"&MONTH(A12),"") -> 2024-5 | K12: =IFERROR(IF(A12<>"",VLOOKUP(B12,'📦 ชื่อสินค้า'!A:F,6,false),""),) -> รุ่นสีอ่อน | L12: =IF(A12<>"",A12,) -> 45430
A13: 45430 | B13: 831 สีโอรส | C13: 150 | D13: โล | E13: 10 | F13: =IF(LEN(B13)>0,C13*E13,"") -> 1500 | G13: =IF(LEN(B13)>0,vlookup(B13,'📊 รายงานสินค้าคงเหลือ'!A:G,6,false)*E13,) -> 800 | H13: =IF(LEN(B13)>0,F13-G13,) -> 700 | I13: =IF(LEN(B13)>0,H13/F13,) -> 0.46666667 | J13: =IF(A13<>"",YEAR(A13)&"-"&MONTH(A13),"") -> 2024-5 | K13: =IFERROR(IF(A13<>"",VLOOKUP(B13,'📦 ชื่อสินค้า'!A:F,6,false),""),) -> รุ่นสีอ่อน | L13: =IF(A13<>"",A13,) -> 45430
A14: 45430 | B14: 552 ชมพูเข้ม | C14: 150 | D14: โล | E14: 10 | F14: =IF(LEN(B14)>0,C14*E14,"") -> 1500 | G14: =IF(LEN(B14)>0,vlookup(B14,'📊 รายงานสินค้าคงเหลือ'!A:G,6,false)*E14,) -> 800 | H14: =IF(LEN(B14)>0,F14-G14,) -> 700 | I14: =IF(LEN(B14)>0,H14/F14,) -> 0.46666667 | J14: =IF(A14<>"",YEAR(A14)&"-"&MONTH(A14),"") -> 2024-5 | K14: =IFERROR(IF(A14<>"",VLOOKUP(B14,'📦 ชื่อสินค้า'!A:F,6,false),""),) -> รุ่นสีอ่อน | L14: =IF(A14<>"",A14,) -> 45430
... A20: 45430 | B20: 882 กาแฟ | C20: 150 | D20: โล | E20: 10 | F20: =IF(LEN(B20)>0,C20*E20,"") -> 1500 | G20: =IF(LEN(B20)>0,vlookup(B20,'📊 รายงานสินค้าคงเหลือ'!A:G,6,false)*E20,) -> #VALUE! | H20: =IF(LEN(B20)>0,F20-G20,) -> #VALUE! | I20: =IF(LEN(B20)>0,H20/F20,) -> #VALUE! | J20: =IF(A20<>"",YEAR(A20)&"-"&MONTH(A20),"") -> 2024-5 | K20: =IFERROR(IF(A20<>"",VLOOKUP(B20,'📦 ชื่อสินค้า'!A:F,6,false),""),) -> รุ่นสีอ่อน | L20: =IF(A20<>"",A20,) -> 45430
D21: โล | F21: =IF(LEN(B21)>0,C21*E21,"") | G21: =IF(LEN(B21)>0,vlookup(B21,'📊 รายงานสินค้าคงเหลือ'!A:G,6,false)*E21,) | H21: =IF(LEN(B21)>0,F21-G21,) | I21: =IF(LEN(B21)>0,H21/F21,) | J21: =IF(A21<>"",YEAR(A21)&"-"&MONTH(A21),"") | K21: =IFERROR(IF(A21<>"",VLOOKUP(B21,'📦 ชื่อสินค้า'!A:F,6,false),""),) | L21: =IF(A21<>"",A21,)
D22: โล | F22: =IF(LEN(B22)>0,C22*E22,"") | G22: =IF(LEN(B22)>0,vlookup(B22,'📊 รายงานสินค้าคงเหลือ'!A:G,6,false)*E22,) | H22: =IF(LEN(B22)>0,F22-G22,) | I22: =IF(LEN(B22)>0,H22/F22,) | J22: =IF(A22<>"",YEAR(A22)&"-"&MONTH(A22),"") | K22: =IFERROR(IF(A22<>"",VLOOKUP(B22,'📦 ชื่อสินค้า'!A:F,6,false),""),) | L22: =IF(A22<>"",A22,)
D23: โล | F23: =IF(LEN(B23)>0,C23*E23,"") | G23: =IF(LEN(B23)>0,vlookup(B23,'📊 รายงานสินค้าคงเหลือ'!A:G,6,false)*E23,) | H23: =IF(LEN(B23)>0,F23-G23,) | I23: =IF(LEN(B23)>0,H23/F23,) | J23: =IF(A23<>"",YEAR(A23)&"-"&MONTH(A23),"") | K23: =IFERROR(IF(A23<>"",VLOOKUP(B23,'📦 ชื่อสินค้า'!A:F,6,false),""),) | L23: =IF(A23<>"",A23,)
D24: โล | F24: =IF(LEN(B24)>0,C24*E24,"") | G24: =IF(LEN(B24)>0,vlookup(B24,'📊 รายงานสินค้าคงเหลือ'!A:G,6,false)*E24,) | H24: =IF(LEN(B24)>0,F24-G24,) | I24: =IF(LEN(B24)>0,H24/F24,) | J24: =IF(A24<>"",YEAR(A24)&"-"&MONTH(A24),"") | K24: =IFERROR(IF(A24<>"",VLOOKUP(B24,'📦 ชื่อสินค้า'!A:F,6,false),""),) | L24: =IF(A24<>"",A24,)
D25: โล | F25: =IF(LEN(B25)>0,C25*E25,"") | G25: =IF(LEN(B25)>0,vlookup(B25,'📊 รายงานสินค้าคงเหลือ'!A:G,6,false)*E25,) | H25: =IF(LEN(B25)>0,F25-G25,) | I25: =IF(LEN(B25)>0,H25/F25,) | J25: =IF(A25<>"",YEAR(A25)&"-"&MONTH(A25),"") | K25: =IFERROR(IF(A25<>"",VLOOKUP(B25,'📦 ชื่อสินค้า'!A:F,6,false),""),) | L25: =IF(A25<>"",A25,)
D26: โล | F26: =IF(LEN(B26)>0,C26*E26,"") | G26: =IF(LEN(B26)>0,vlookup(B26,'📊 รายงานสินค้าคงเหลือ'!A:G,6,false)*E26,) | H26: =IF(LEN(B26)>0,F26-G26,) | I26: =IF(LEN(B26)>0,H26/F26,) | J26: =IF(A26<>"",YEAR(A26)&"-"&MONTH(A26),"") | K26: =IFERROR(IF(A26<>"",VLOOKUP(B26,'📦 ชื่อสินค้า'!A:F,6,false),""),) | L26: =IF(A26<>"",A26,)
D27: โล | F27: =IF(LEN(B27)>0,C27*E27,"") | G27: =IF(LEN(B27)>0,vlookup(B27,'📊 รายงานสินค้าคงเหลือ'!A:G,6,false)*E27,) | H27: =IF(LEN(B27)>0,F27-G27,) | I27: =IF(LEN(B27)>0,H27/F27,) | J27: =IF(A27<>"",YEAR(A27)&"-"&MONTH(A27),"") | K27: =IFERROR(IF(A27<>"",VLOOKUP(B27,'📦 ชื่อสินค้า'!A:F,6,false),""),) | L27: =IF(A27<>"",A27,)
F28: =IF(LEN(B28)>0,C28*E28,"") | G28: =IF(LEN(B28)>0,vlookup(B28,'📊 รายงานสินค้าคงเหลือ'!A:G,6,false)*E28,) | H28: =IF(LEN(B28)>0,F28-G28,) | I28: =IF(LEN(B28)>0,H28/F28,) | J28: =IF(A28<>"",YEAR(A28)&"-"&MONTH(A28),"") | K28: =IFERROR(IF(A28<>"",VLOOKUP(B28,'📦 ชื่อสินค้า'!A:F,6,false),""),) | L28: =IF(A28<>"",A28,)
F29: =IF(LEN(B29)>0,C29*E29,"") | G29: =IF(LEN(B29)>0,vlookup(B29,'📊 รายงานสินค้าคงเหลือ'!A:G,6,false)*E29,) | H29: =IF(LEN(B29)>0,F29-G29,) | I29: =IF(LEN(B29)>0,H29/F29,) | J29: =IF(A29<>"",YEAR(A29)&"-"&MONTH(A29),"") | K29: =IFERROR(IF(A29<>"",VLOOKUP(B29,'📦 ชื่อสินค้า'!A:F,6,false),""),) | L29: =IF(A29<>"",A29,)
F30: =IF(LEN(B30)>0,C30*E30,"") | G30: =IF(LEN(B30)>0,vlookup(B30,'📊 รายงานสินค้าคงเหลือ'!A:G,6,false)*E30,) | H30: =IF(LEN(B30)>0,F30-G30,) | I30: =IF(LEN(B30)>0,H30/F30,) | J30: =IF(A30<>"",YEAR(A30)&"-"&MONTH(A30),"") | K30: =IFERROR(IF(A30<>"",VLOOKUP(B30,'📦 ชื่อสินค้า'!A:F,6,false),""),) | L30: =IF(A30<>"",A30,)
F31: =IF(LEN(B31)>0,C31*E31,"") | G31: =IF(LEN(B31)>0,vlookup(B31,'📊 รายงานสินค้าคงเหลือ'!A:G,6,false)*E31,) | H31: =IF(LEN(B31)>0,F31-G31,) | I31: =IF(LEN(B31)>0,H31/F31,) | J31: =IF(A31<>"",YEAR(A31)&"-"&MONTH(A31),"") | K31: =IFERROR(IF(A31<>"",VLOOKUP(B31,'📦 ชื่อสินค้า'!A:F,6,false),""),) | L31: =IF(A31<>"",A31,)
F32: =IF(LEN(B32)>0,C32*E32,"") | G32: =IF(LEN(B32)>0,vlookup(B32,'📊 รายงานสินค้าคงเหลือ'!A:G,6,false)*E32,) | H32: =IF(LEN(B32)>0,F32-G32,) | I32: =IF(LEN(B32)>0,H32/F32,) | J32: =IF(A32<>"",YEAR(A32)&"-"&MONTH(A32),"") | K32: =IFERROR(IF(A32<>"",VLOOKUP(B32,'📦 ชื่อสินค้า'!A:F,6,false),""),) | L32: =IF(A32<>"",A32,)
F33: =IF(LEN(B33)>0,C33*E33,"") | G33: =IF(LEN(B33)>0,vlookup(B33,'📊 รายงานสินค้าคงเหลือ'!A:G,6,false)*E33,) | H33: =IF(LEN(B33)>0,F33-G33,) | I33: =IF(LEN(B33)>0,H33/F33,) | J33: =IF(A33<>"",YEAR(A33)&"-"&MONTH(A33),"") | K33: =IFERROR(IF(A33<>"",VLOOKUP(B33,'📦 ชื่อสินค้า'!A:F,6,false),""),) | L33: =IF(A33<>"",A33,)
F34: =IF(LEN(B34)>0,C34*E34,"") | G34: =IF(LEN(B34)>0,vlookup(B34,'📊 รายงานสินค้าคงเหลือ'!A:G,6,false)*E34,) | H34: =IF(LEN(B34)>0,F34-G34,) | I34: =IF(LEN(B34)>0,H34/F34,) | J34: =IF(A34<>"",YEAR(A34)&"-"&MONTH(A34),"") | K34: =IFERROR(IF(A34<>"",VLOOKUP(B34,'📦 ชื่อสินค้า'!A:F,6,false),""),) | L34: =IF(A34<>"",A34,)
C35: =iferror(vlookup(B35,'📦 ชื่อสินค้า'!A:C,3,false),) | D35: =iferror(vlookup(B35,'📦 ชื่อสินค้า'!A:D,4,false),"") | F35: =IF(LEN(B35)>0,C35*E35,"") | G35: =IF(LEN(B35)>0,vlookup(B35,'📊 รายงานสินค้าคงเหลือ'!A:G,6,false)*E35,) | H35: =IF(LEN(B35)>0,F35-G35,) | I35: =IF(LEN(B35)>0,H35/F35,) | J35: =IF(A35<>"",YEAR(A35)&"-"&MONTH(A35),"") | K35: =IFERROR(IF(A35<>"",VLOOKUP(B35,'📦 ชื่อสินค้า'!A:F,6,false),""),) | L35: =IF(A35<>"",A35,)
C36: =iferror(vlookup(B36,'📦 ชื่อสินค้า'!A:C,3,false),) | D36: =iferror(vlookup(B36,'📦 ชื่อสินค้า'!A:D,4,false),"") | F36: =IF(LEN(B36)>0,C36*E36,"") | G36: =IF(LEN(B36)>0,vlookup(B36,'📊 รายงานสินค้าคงเหลือ'!A:G,6,false)*E36,) | H36: =IF(LEN(B36)>0,F36-G36,) | I36: =IF(LEN(B36)>0,H36/F36,) | J36: =IF(A36<>"",YEAR(A36)&"-"&MONTH(A36),"") | K36: =IFERROR(IF(A36<>"",VLOOKUP(B36,'📦 ชื่อสินค้า'!A:F,6,false),""),) | L36: =IF(A36<>"",A36,)
C37: =iferror(vlookup(B37,'📦 ชื่อสินค้า'!A:C,3,false),) | D37: =iferror(vlookup(B37,'📦 ชื่อสินค้า'!A:D,4,false),"") | F37: =IF(LEN(B37)>0,C37*E37,"") | G37: =IF(LEN(B37)>0,vlookup(B37,'📊 รายงานสินค้าคงเหลือ'!A:G,6,false)*E37,) | H37: =IF(LEN(B37)>0,F37-G37,) | I37: =IF(LEN(B37)>0,H37/F37,) | J37: =IF(A37<>"",YEAR(A37)&"-"&MONTH(A37),"") | K37: =IFERROR(IF(A37<>"",VLOOKUP(B37,'📦 ชื่อสินค้า'!A:F,6,false),""),) | L37: =IF(A37<>"",A37,)
C38: =iferror(vlookup(B38,'📦 ชื่อสินค้า'!A:C,3,false),) | D38: =iferror(vlookup(B38,'📦 ชื่อสินค้า'!A:D,4,false),"") | F38: =IF(LEN(B38)>0,C38*E38,"") | G38: =IF(LEN(B38)>0,vlookup(B38,'📊 รายงานสินค้าคงเหลือ'!A:G,6,false)*E38,) | H38: =IF(LEN(B38)>0,F38-G38,) | I38: =IF(LEN(B38)>0,H38/F38,) | J38: =IF(A38<>"",YEAR(A38)&"-"&MONTH(A38),"") | K38: =IFERROR(IF(A38<>"",VLOOKUP(B38,'📦 ชื่อสินค้า'!A:F,6,false),""),) | L38: =IF(A38<>"",A38,)
C39: =iferror(vlookup(B39,'📦 ชื่อสินค้า'!A:C,3,false),) | D39: =iferror(vlookup(B39,'📦 ชื่อสินค้า'!A:D,4,false),"") | F39: =IF(LEN(B39)>0,C39*E39,"") | G39: =IF(LEN(B39)>0,vlookup(B39,'📊 รายงานสินค้าคงเหลือ'!A:G,6,false)*E39,) | H39: =IF(LEN(B39)>0,F39-G39,) | I39: =IF(LEN(B39)>0,H39/F39,) | J39: =IF(A39<>"",YEAR(A39)&"-"&MONTH(A39),"") | K39: =IFERROR(IF(A39<>"",VLOOKUP(B39,'📦 ชื่อสินค้า'!A:F,6,false),""),) | L39: =IF(A39<>"",A39,)
C40: =iferror(vlookup(B40,'📦 ชื่อสินค้า'!A:C,3,false),) | D40: =iferror(vlookup(B40,'📦 ชื่อสินค้า'!A:D,4,false),"") | F40: =IF(LEN(B40)>0,C40*E40,"") | G40: =IF(LEN(B40)>0,vlookup(B40,'📊 รายงานสินค้าคงเหลือ'!A:G,6,false)*E40,) | H40: =IF(LEN(B40)>0,F40-G40,) | I40: =IF(LEN(B40)>0,H40/F40,) | J40: =IF(A40<>"",YEAR(A40)&"-"&MONTH(A40),"") | K40: =IFERROR(IF(A40<>"",VLOOKUP(B40,'📦 ชื่อสินค้า'!A:F,6,false),""),) | L40: =IF(A40<>"",A40,)
C41: =iferror(vlookup(B41,'📦 ชื่อสินค้า'!A:C,3,false),) | D41: =iferror(vlookup(B41,'📦 ชื่อสินค้า'!A:D,4,false),"") | F41: =IF(LEN(B41)>0,C41*E41,"") | G41: =IF(LEN(B41)>0,vlookup(B41,'📊 รายงานสินค้าคงเหลือ'!A:G,6,false)*E41,) | H41: =IF(LEN(B41)>0,F41-G41,) | I41: =IF(LEN(B41)>0,H41/F41,) | J41: =IF(A41<>"",YEAR(A41)&"-"&MONTH(A41),"") | K41: =IFERROR(IF(A41<>"",VLOOKUP(B41,'📦 ชื่อสินค้า'!A:F,6,false),""),) | L41: =IF(A41<>"",A41,)
C42: =iferror(vlookup(B42,'📦 ชื่อสินค้า'!A:C,3,false),) | D42: =iferror(vlookup(B42,'📦 ชื่อสินค้า'!A:D,4,false),"") | F42: =IF(LEN(B42)>0,C42*E42,"") | G42: =IF(LEN(B42)>0,vlookup(B42,'📊 รายงานสินค้าคงเหลือ'!A:G,6,false)*E42,) | H42: =IF(LEN(B42)>0,F42-G42,) | I42: =IF(LEN(B42)>0,H42/F42,) | J42: =IF(A42<>"",YEAR(A42)&"-"&MONTH(A42),"") | K42: =IFERROR(IF(A42<>"",VLOOKUP(B42,'📦 ชื่อสินค้า'!A:F,6,false),""),) | L42: =IF(A42<>"",A42,)
C43: =iferror(vlookup(B43,'📦 ชื่อสินค้า'!A:C,3,false),) | D43: =iferror(vlookup(B43,'📦 ชื่อสินค้า'!A:D,4,false),"") | F43: =IF(LEN(B43)>0,C43*E43,"") | G43: =IF(LEN(B43)>0,vlookup(B43,'📊 รายงานสินค้าคงเหลือ'!A:G,6,false)*E43,) | H43: =IF(LEN(B43)>0,F43-G43,) | I43: =IF(LEN(B43)>0,H43/F43,) | J43: =IF(A43<>"",YEAR(A43)&"-"&MONTH(A43),"") | K43: =IFERROR(IF(A43<>"",VLOOKUP(B43,'📦 ชื่อสินค้า'!A:F,6,false),""),) | L43: =IF(A43<>"",A43,)
C44: =iferror(vlookup(B44,'📦 ชื่อสินค้า'!A:C,3,false),) | D44: =iferror(vlookup(B44,'📦 ชื่อสินค้า'!A:D,4,false),"") | F44: =IF(LEN(B44)>0,C44*E44,"") | G44: =IF(LEN(B44)>0,vlookup(B44,'📊 รายงานสินค้าคงเหลือ'!A:G,6,false)*E44,) | H44: =IF(LEN(B44)>0,F44-G44,) | I44: =IF(LEN(B44)>0,H44/F44,) | J44: =IF(A44<>"",YEAR(A44)&"-"&MONTH(A44),"") | K44: =IFERROR(IF(A44<>"",VLOOKUP(B44,'📦 ชื่อสินค้า'!A:F,6,false),""),) | L44: =IF(A44<>"",A44,)
C45: =iferror(vlookup(B45,'📦 ชื่อสินค้า'!A:C,3,false),) | D45: =iferror(vlookup(B45,'📦 ชื่อสินค้า'!A:D,4,false),"") | F45: =IF(LEN(B45)>0,C45*E45,"") | G45: =IF(LEN(B45)>0,vlookup(B45,'📊 รายงานสินค้าคงเหลือ'!A:G,6,false)*E45,) | H45: =IF(LEN(B45)>0,F45-G45,) | I45: =IF(LEN(B45)>0,H45/F45,) | J45: =IF(A45<>"",YEAR(A45)&"-"&MONTH(A45),"") | K45: =IFERROR(IF(A45<>"",VLOOKUP(B45,'📦 ชื่อสินค้า'!A:F,6,false),""),) | L45: =IF(A45<>"",A45,)
...

Sheet 💸 Transaction ซื้อ
A1: วันที่ | B1: ชื่อสินค้า | C1: ราคา | D1: หน่วยนับ | E1: ตัดได้จริง | F1: ต้นทุนอื่นๆ | G1: มูลค่ารวม | H1: ปีเดือน | I1: สั่งมา
A2: 45437 | B2: 510 ขาวธรรมชาติ | C2: 80 | D2: =iferror(vlookup(B2,'📦 ชื่อสินค้า'!A:D,4,false),"") -> โล | E2: 507 | G2: =IF(LEN(B2)>0,C2*E2+F2,"") -> 40560 | H2: =IF(A2<>"",YEAR(A2)&"-"&MONTH(A2),"") -> 2024-5 | I2: 507
A3: 45433 | B3: 861 ฟ้าอ่อน | C3: 90 | D3: โล | E3: 114 | G3: =IF(LEN(B3)>0,C3*E3+F3,"") -> 10260 | H3: =IF(A3<>"",YEAR(A3)&"-"&MONTH(A3),"") -> 2024-5 | I3: 114
A4: 45393 | B4: 831 สีโอรส | C4: 80 | D4: โล | E4: 118 | G4: =IF(LEN(B4)>0,C4*E4+F4,"") -> 9440 | H4: =IF(A4<>"",YEAR(A4)&"-"&MONTH(A4),"") -> 2024-4 | I4: 114
A5: 45393 | B5: 552 ชมพูเข้ม | C5: 80 | D5: โล | E5: 160 | G5: =IF(LEN(B5)>0,C5*E5+F5,"") -> 12800 | H5: =IF(A5<>"",YEAR(A5)&"-"&MONTH(A5),"") -> 2024-4 | I5: 157
A6: 45393 | B6: 551 ชมพูอ่อน | C6: 80 | D6: โล | E6: 473 | G6: =IF(LEN(B6)>0,C6*E6+F6,"") -> 37840 | H6: =IF(A6<>"",YEAR(A6)&"-"&MONTH(A6),"") -> 2024-4 | I6: 473
A7: 45393 | B7: 561 ฟ้าเข้ม | C7: 80 | D7: โล | E7: 94 | G7: =IF(LEN(B7)>0,C7*E7+F7,"") -> 7520 | H7: =IF(A7<>"",YEAR(A7)&"-"&MONTH(A7),"") -> 2024-4 | I7: 90
A8: 45393 | B8: 860 ม่วงอ่อน | C8: 80 | D8: โล | E8: 190 | G8: =IF(LEN(B8)>0,C8*E8+F8,"") -> 15200 | H8: =IF(A8<>"",YEAR(A8)&"-"&MONTH(A8),"") -> 2024-4 | I8: 183
A9: 45393 | B9: 591 เทาอ่อน | C9: 70 | D9: โล | E9: 130 | G9: =IF(LEN(B9)>0,C9*E9+F9,"") -> 9100 | H9: =IF(A9<>"",YEAR(A9)&"-"&MONTH(A9),"") -> 2024-4 | I9: 130
A10: 45364 | B10: 521 ครีม | C10: 80 | D10: โล | E10: 467 | G10: =IF(LEN(B10)>0,C10*E10+F10,"") -> 37360 | H10: =IF(A10<>"",YEAR(A10)&"-"&MONTH(A10),"") -> 2024-3 | I10: 470
A11: 45364 | B11: 510 ขาวธรรมชาติ | C11: 90 | D11: โล | E11: 398 | G11: =IF(LEN(B11)>0,C11*E11+F11,"") -> 35820 | H11: =IF(A11<>"",YEAR(A11)&"-"&MONTH(A11),"") -> 2024-3 | I11: 380
A12: 45362 | B12: 111 เงินเงา | C12: 250 | D12: โล | E12: 335 | G12: =IF(LEN(B12)>0,C12*E12+F12,"") -> 83750 | H12: =IF(A12<>"",YEAR(A12)&"-"&MONTH(A12),"") -> 2024-3 | I12: 335
A13: 45362 | B13: 112 เงินด้าน | C13: 250 | D13: โล | E13: 335 | G13: =IF(LEN(B13)>0,C13*E13+F13,"") -> 83750 | H13: =IF(A13<>"",YEAR(A13)&"-"&MONTH(A13),"") -> 2024-3 | I13: 335
A14: 45447 | B14: 521 ครีม | C14: 80 | D14: โล | E14: 473 | G14: =IF(LEN(B14)>0,C14*E14+F14,"") -> 37840 | H14: =IF(A14<>"",YEAR(A14)&"-"&MONTH(A14),"") -> 2024-6 | I14: 473
... A16: 45454 | B16: 863 ฟ้าพาสเทลเข้ม | C16: 80 | D16: โล | E16: 68 | G16: =IF(LEN(B16)>0,C16*E16+F16,"") -> 5440 | H16: =IF(A16<>"",YEAR(A16)&"-"&MONTH(A16),"") -> 2024-6 | I16: 68
A17: 45456 | B17: 571 เขียวหยก | C17: 80 | D17: โล | G17: =IF(LEN(B17)>0,C17*E17+F17,"") -> 0 | H17: =IF(A17<>"",YEAR(A17)&"-"&MONTH(A17),"") -> 2024-6 | I17: 118
G18: =IF(LEN(B18)>0,C18*E18+F18,"") | H18: =IF(A18<>"",YEAR(A18)&"-"&MONTH(A18),"")
G19: =IF(LEN(B19)>0,C19*E19+F19,"") | H19: =IF(A19<>"",YEAR(A19)&"-"&MONTH(A19),"")
G20: =IF(LEN(B20)>0,C20*E20+F20,"") | H20: =IF(A20<>"",YEAR(A20)&"-"&MONTH(A20),"")
G21: =IF(LEN(B21)>0,C21*E21+F21,"") | H21: =IF(A21<>"",YEAR(A21)&"-"&MONTH(A21),"")
G22: =IF(LEN(B22)>0,C22*E22+F22,"") | H22: =IF(A22<>"",YEAR(A22)&"-"&MONTH(A22),"")
G23: =IF(LEN(B23)>0,C23*E23+F23,"") | H23: =IF(A23<>"",YEAR(A23)&"-"&MONTH(A23),"")
G24: =IF(LEN(B24)>0,C24*E24+F24,"") | H24: =IF(A24<>"",YEAR(A24)&"-"&MONTH(A24),"")
G25: =IF(LEN(B25)>0,C25*E25+F25,"") | H25: =IF(A25<>"",YEAR(A25)&"-"&MONTH(A25),"")
C26: =iferror(vlookup(B26,'📦 ชื่อสินค้า'!A:C,2,false),) | D26: =iferror(vlookup(B26,'📦 ชื่อสินค้า'!A:D,4,false),"") | G26: =IF(LEN(B26)>0,C26*E26+F26,"") | H26: =IF(A26<>"",YEAR(A26)&"-"&MONTH(A26),"")
C27: =iferror(vlookup(B27,'📦 ชื่อสินค้า'!A:C,2,false),) | D27: =iferror(vlookup(B27,'📦 ชื่อสินค้า'!A:D,4,false),"") | G27: =IF(LEN(B27)>0,C27*E27+F27,"") | H27: =IF(A27<>"",YEAR(A27)&"-"&MONTH(A27),"")
C28: =iferror(vlookup(B28,'📦 ชื่อสินค้า'!A:C,2,false),) | D28: =iferror(vlookup(B28,'📦 ชื่อสินค้า'!A:D,4,false),"") | G28: =IF(LEN(B28)>0,C28*E28+F28,"") | H28: =IF(A28<>"",YEAR(A28)&"-"&MONTH(A28),"")
C29: =iferror(vlookup(B29,'📦 ชื่อสินค้า'!A:C,2,false),) | D29: =iferror(vlookup(B29,'📦 ชื่อสินค้า'!A:D,4,false),"") | G29: =IF(LEN(B29)>0,C29*E29+F29,"") | H29: =IF(A29<>"",YEAR(A29)&"-"&MONTH(A29),"")
C30: =iferror(vlookup(B30,'📦 ชื่อสินค้า'!A:C,2,false),) | D30: =iferror(vlookup(B30,'📦 ชื่อสินค้า'!A:D,4,false),"") | G30: =IF(LEN(B30)>0,C30*E30+F30,"") | H30: =IF(A30<>"",YEAR(A30)&"-"&MONTH(A30),"")
C31: =iferror(vlookup(B31,'📦 ชื่อสินค้า'!A:C,2,false),) | D31: =iferror(vlookup(B31,'📦 ชื่อสินค้า'!A:D,4,false),"") | G31: =IF(LEN(B31)>0,C31*E31+F31,"") | H31: =IF(A31<>"",YEAR(A31)&"-"&MONTH(A31),"")
C32: =iferror(vlookup(B32,'📦 ชื่อสินค้า'!A:C,2,false),) | D32: =iferror(vlookup(B32,'📦 ชื่อสินค้า'!A:D,4,false),"") | G32: =IF(LEN(B32)>0,C32*E32+F32,"") | H32: =IF(A32<>"",YEAR(A32)&"-"&MONTH(A32),"")
C33: =iferror(vlookup(B33,'📦 ชื่อสินค้า'!A:C,2,false),) | D33: =iferror(vlookup(B33,'📦 ชื่อสินค้า'!A:D,4,false),"") | G33: =IF(LEN(B33)>0,C33*E33+F33,"") | H33: =IF(A33<>"",YEAR(A33)&"-"&MONTH(A33),"")
C34: =iferror(vlookup(B34,'📦 ชื่อสินค้า'!A:C,2,false),) | D34: =iferror(vlookup(B34,'📦 ชื่อสินค้า'!A:D,4,false),"") | G34: =IF(LEN(B34)>0,C34*E34+F34,"") | H34: =IF(A34<>"",YEAR(A34)&"-"&MONTH(A34),"")
C35: =iferror(vlookup(B35,'📦 ชื่อสินค้า'!A:C,2,false),) | D35: =iferror(vlookup(B35,'📦 ชื่อสินค้า'!A:D,4,false),"") | G35: =IF(LEN(B35)>0,C35*E35+F35,"") | H35: =IF(A35<>"",YEAR(A35)&"-"&MONTH(A35),"")
C36: =iferror(vlookup(B36,'📦 ชื่อสินค้า'!A:C,2,false),) | D36: =iferror(vlookup(B36,'📦 ชื่อสินค้า'!A:D,4,false),"") | G36: =IF(LEN(B36)>0,C36*E36+F36,"") | H36: =IF(A36<>"",YEAR(A36)&"-"&MONTH(A36),"")
C37: =iferror(vlookup(B37,'📦 ชื่อสินค้า'!A:C,2,false),) | D37: =iferror(vlookup(B37,'📦 ชื่อสินค้า'!A:D,4,false),"") | G37: =IF(LEN(B37)>0,C37*E37+F37,"") | H37: =IF(A37<>"",YEAR(A37)&"-"&MONTH(A37),"")
... C996: =iferror(vlookup(B996,'📦 ชื่อสินค้า'!A:C,2,false),) | D996: =iferror(vlookup(B996,'📦 ชื่อสินค้า'!A:D,4,false),"") | G996: =IF(LEN(B996)>0,C996*E996+F996,"") | H996: =IF(A996<>"",YEAR(A996)&"-"&MONTH(A996),"")

Sheet 📦 ชื่อสินค้า
A1: ชื่อสินค้า | B1: ราคาซื้อ | C1: ราคาขาย | D1: หน่วยนับ | E1: จำนวนขั้นต่ำ | F1: กลุ่มสินค้า | G1: Status
A2: 510 ขาวธรรมชาติ | B2: 90 | C2: 150 | D2: โล | E2: 50 | F2: รุ่นสีอ่อน | G2: Active
A3: 861 ฟ้าอ่อน | B3: 80 | C3: 150 | D3: โล | E3: 5 | F3: รุ่นสีอ่อน | G3: Active
A4: 831 สีโอรส | B4: 80 | C4: 150 | D4: โล | E4: 5 | F4: รุ่นสีอ่อน | G4: Active
A5: 552 ชมพูเข้ม | B5: 80 | C5: 150 | D5: โล | E5: 5 | F5: รุ่นสีอ่อน | G5: Active
A6: 551 ชมพูอ่อน | B6: 80 | C6: 150 | D6: โล | E6: 5 | F6: รุ่นสีอ่อน | G6: Active
A7: 860 ม่วงอ่อน | B7: 80 | C7: 150 | D7: โล | E7: 5 | F7: รุ่นสีอ่อน | G7: Active
A8: 591 เทาอ่อน | B8: 70 | C8: 150 | D8: โล | E8: 5 | F8: รุ่นสีอ่อน | G8: Active
A9: 561 ฟ้าเข้ม | B9: 80 | C9: 150 | D9: โล | E9: 5 | F9: รุ่นสีอ่อน | G9: Active
A10: 521 ครีม | B10: 80 | C10: 150 | D10: โล | E10: 10 | F10: รุ่นสีอ่อน | G10: Active
A11: 111 เงินเงา | B11: 250 | C11: 400 | D11: โล | E11: 50 | F11: รุ่นสีพิเศษ A | G11: Active
A12: 112 เงินด้าน | B12: 250 | C12: 400 | D12: โล | E12: 20 | F12: รุ่นสีพิเศษ A | G12: Active
A13: 881 เปลือกไม้ | B13: 80 | C13: 150 | D13: โล | E13: 20 | F13: รุ่นสีอ่อน | G13: Active
... A15: 881 เปลือกไม้ รุ่นหยัก | B15: 20 | C15: 250 | D15: โล | E15: 5 | F15: รุ่นหยัก | G15: Active
A16: 853 ชมพูพาสเทล | B16: 80 | C16: 150 | D16: โล | E16: 5 | F16: รุ่นสีอ่อน
A17: 862 ฟ้า PT อ่อน | B17: 80 | C17: 150 | D17: โล | E17: 5 | F17: รุ่นสีอ่อน
A18: 863 ฟ้า PT เข้ม | B18: 80 | C18: 150 | D18: โล | E18: 5 | F18: รุ่นสีอ่อน
A19: 522 เหลืองอ่อน | B19: 60 | C19: 150 | D19: โล | E19: 5 | F19: รุ่นสีอ่อน
A20: 571 เขียวหยก | B20: 60 | C20: 150 | D20: โล | E20: 5 | F20: รุ่นสีอ่อน
A21: 882 กาแฟ | B21: 60 | C21: 150 | D21: โล | E21: 5 | F21: รุ่นสีอ่อน
A22: 511 กรีนรีด | B22: 60 | C22: 150 | D22: โล | E22: 5 | F22: รุ่นสีอ่อน

Sheet ช่องทางการขาย
A1: ชื่อสินค้า | B1: ราคาซื้อ | C1: ราคาขาย | D1: หน่วยนับ | E1: จำนวนขั้นต่ำ | F1: กลุ่มสินค้า | G1: Status
A2: 510 ขาวธรรมชาติ | B2: 90 | C2: 150 | D2: โล | E2: 50 | F2: รุ่นสีอ่อน | G2: Active
A3: 861 ฟ้าอ่อน | B3: 80 | C3: 150 | D3: โล | E3: 5 | F3: รุ่นสีอ่อน | G3: Active
A4: 831 สีโอรส | B4: 80 | C4: 150 | D4: โล | E4: 5 | F4: รุ่นสีอ่อน | G4: Active
A5: 552 ชมพูเข้ม | B5: 80 | C5: 150 | D5: โล | E5: 5 | F5: รุ่นสีอ่อน | G5: Active
A6: 551 ชมพูอ่อน | B6: 80 | C6: 150 | D6: โล | E6: 5 | F6: รุ่นสีอ่อน | G6: Active
A7: 860 ม่วงอ่อน | B7: 80 | C7: 150 | D7: โล | E7: 5 | F7: รุ่นสีอ่อน | G7: Active
A8: 591 เทาอ่อน | B8: 70 | C8: 150 | D8: โล | E8: 5 | F8: รุ่นสีอ่อน | G8: Active
A9: 561 ฟ้าเข้ม | B9: 80 | C9: 150 | D9: โล | E9: 5 | F9: รุ่นสีอ่อน | G9: Active
A10: 521 ครีม | B10: 80 | C10: 150 | D10: โล | E10: 10 | F10: รุ่นสีอ่อน | G10: Active
A11: 111 เงินเงา | B11: 250 | C11: 400 | D11: โล | E11: 50 | F11: รุ่นสีพิเศษ A | G11: Active
A12: 112 เงินด้าน | B12: 250 | C12: 400 | D12: โล | E12: 20 | F12: รุ่นสีพิเศษ A | G12: Active

Sheet 📊 รายงานสินค้าคงเหลือ
A1: =IFERROR(__xludf.DUMMYFUNCTION("query('📦 ชื่อสินค้า'!A:A,""select *"",1)"),"ชื่อสินค้า") -> ชื่อสินค้า | B1: จำนวนสินค้าคงเหลือ | C1: จำนวนขั้นต่ำ | D1: กลุ่มสินค้า | E1: สถานะการเติมสินค้า | F1: ต้นทุนเฉลี่ยต่อชิ้น | G1: ต้นทุนรวมปัจจุบัน | H1: {={"วันที่ขายล่าสุด";IFERROR(IF(A2:A1000<>"",VLOOKUP(A2:A1000,SORT('💰 Transaction ขาย'!B:L,1,false,11,false),11,false),),"-")}} -> วันที่ขายล่าสุด | I1: {={"จำนวนวันที่ไม่เคลื่อนไหว";IFERROR(IF(E2:E1000="InActive","-",IF(H2:H1000<>"",'⚙️ Config'!$H$1-H2:H1000,)),"-")}} -> จำนวนวันที่ไม่เคลื่อนไหว | J1: {={"ประเภทการเคลื่อนไหวสินค้า";IFERROR(IF(E2:E1000="InActive","InActive",IF(A2:A1000<>"",VLOOKUP(I2:I1000,'⚙️ Config'!$J$2:$K$6,2,1),)),"-")}} -> ประเภทการเคลื่อนไหวสินค้า | K1: ="อัตราขายเฉลี่ยใน "&'⚙️ Config'!H2&" วัน ที่ผ่านมา" -> อัตราขายเฉลี่ยใน 30 วัน ที่ผ่านมา | L1: อัตราขายเฉลี่ยต่อวัน | M1: จำนวนเดือนที่คาดว่าจะขายสินค้าหมด (MOS) | N1: ยอดขายรวมของปีนี้
A2: =IFERROR(__xludf.DUMMYFUNCTION("""COMPUTED_VALUE"""),"510 ขาวธรรมชาติ") -> 510 ขาวธรรมชาติ | B2: =IF(A2<>"",SUMIFS('💸 Transaction ซื้อ'!E:E,'💸 Transaction ซื้อ'!B:B,A2)-SUMIFS('💰 Transaction ขาย'!E:E,'💰 Transaction ขาย'!B:B,A2),"") -> 885 | C2: =IF(A2<>"",vlookup(A2,'📦 ชื่อสินค้า'!A:E,5,false),"") -> 50 | D2: =IF(A2<>"",VLOOKUP(A2,'📦 ชื่อสินค้า'!A:F,6,false),"") -> รุ่นสีอ่อน | E2: =IFERROR(IF(VLOOKUP(A2,'📦 ชื่อสินค้า'!A:G,7,false)="InActive","InActive",IF(A2<>"",IF(B2<=0,"สินค้าหมด",IF(B2<=C2,"ควรเติมทันที","OK")),"")),) -> OK | F2: =IFERROR(IF(A2<>"", SUMIF('💸 Transaction ซื้อ'!B:B,A2,'💸 Transaction ซื้อ'!G:G)/SUMIF('💸 Transaction ซื้อ'!B:B,A2,'💸 Transaction ซื้อ'!E:E),""),"-") -> 84.39779 | G2: =IFERROR(IF(A2<>"",F2*B2,""),"-") -> 74692.044 | H2: 45430 | I2: 692 | J2: Deadstock | K2: =IF(A2<>"",IF(E2="InActive","-",SUMIFS('💰 Transaction ขาย'!E:E,'💰 Transaction ขาย'!B:B,A2,'💰 Transaction ขาย'!A:A,">"&'⚙️ Config'!$H$1-'⚙️ Config'!$H$2)),) -> 0 | L2: =IF(E2="InActive","-",IF(A2<>"",K2/'⚙️ Config'!$H$2,)) -> 0 | M2: =IF(E2="InActive","-",IF(L2<>"",(B2/L2)/30,)) -> #DIV/0! | N2: =IF(A2<>"", SUMIFS('💰 Transaction ขาย'!F:F,'💰 Transaction ขาย'!B:B,A2,'💰 Transaction ขาย'!A:A,">="&DATE(YEAR('⚙️ Config'!$H$1),1,1),'💰 Transaction ขาย'!A:A,"<="&DATE(YEAR('⚙️ Config'!$H$1),12,31)),) -> 0
A3: =IFERROR(__xludf.DUMMYFUNCTION("""COMPUTED_VALUE"""),"861 ฟ้าอ่อน") -> 861 ฟ้าอ่อน | B3: =IF(A3<>"",SUMIFS('💸 Transaction ซื้อ'!E:E,'💸 Transaction ซื้อ'!B:B,A3)-SUMIFS('💰 Transaction ขาย'!E:E,'💰 Transaction ขาย'!B:B,A3),"") -> 114 | C3: =IF(A3<>"",vlookup(A3,'📦 ชื่อสินค้า'!A:E,5,false),"") -> 5 | D3: =IF(A3<>"",VLOOKUP(A3,'📦 ชื่อสินค้า'!A:F,6,false),"") -> รุ่นสีอ่อน | E3: =IFERROR(IF(VLOOKUP(A3,'📦 ชื่อสินค้า'!A:G,7,false)="InActive","InActive",IF(A3<>"",IF(B3<=0,"สินค้าหมด",IF(B3<=C3,"ควรเติมทันที","OK")),"")),) -> OK | F3: =IFERROR(IF(A3<>"", SUMIF('💸 Transaction ซื้อ'!B:B,A3,'💸 Transaction ซื้อ'!G:G)/SUMIF('💸 Transaction ซื้อ'!B:B,A3,'💸 Transaction ซื้อ'!E:E),""),"-") -> 90 | G3: =IFERROR(IF(A3<>"",F3*B3,""),"-") -> 10260 | H3: - | I3: - | J3: - | K3: =IF(A3<>"",IF(E3="InActive","-",SUMIFS('💰 Transaction ขาย'!E:E,'💰 Transaction ขาย'!B:B,A3,'💰 Transaction ขาย'!A:A,">"&'⚙️ Config'!$H$1-'⚙️ Config'!$H$2)),) -> 0 | L3: =IF(E3="InActive","-",IF(A3<>"",K3/'⚙️ Config'!$H$2,)) -> 0 | M3: =IF(E3="InActive","-",IF(L3<>"",(B3/L3)/30,)) -> #DIV/0! | N3: =IF(A3<>"", SUMIFS('💰 Transaction ขาย'!F:F,'💰 Transaction ขาย'!B:B,A3,'💰 Transaction ขาย'!A:A,">="&DATE(YEAR('⚙️ Config'!$H$1),1,1),'💰 Transaction ขาย'!A:A,"<="&DATE(YEAR('⚙️ Config'!$H$1),12,31)),) -> 0
A4: =IFERROR(__xludf.DUMMYFUNCTION("""COMPUTED_VALUE"""),"831 สีโอรส") -> 831 สีโอรส | B4: =IF(A4<>"",SUMIFS('💸 Transaction ซื้อ'!E:E,'💸 Transaction ซื้อ'!B:B,A4)-SUMIFS('💰 Transaction ขาย'!E:E,'💰 Transaction ขาย'!B:B,A4),"") -> 105 | C4: =IF(A4<>"",vlookup(A4,'📦 ชื่อสินค้า'!A:E,5,false),"") -> 5 | D4: =IF(A4<>"",VLOOKUP(A4,'📦 ชื่อสินค้า'!A:F,6,false),"") -> รุ่นสีอ่อน | E4: =IFERROR(IF(VLOOKUP(A4,'📦 ชื่อสินค้า'!A:G,7,false)="InActive","InActive",IF(A4<>"",IF(B4<=0,"สินค้าหมด",IF(B4<=C4,"ควรเติมทันที","OK")),"")),) -> OK | F4: =IFERROR(IF(A4<>"", SUMIF('💸 Transaction ซื้อ'!B:B,A4,'💸 Transaction ซื้อ'!G:G)/SUMIF('💸 Transaction ซื้อ'!B:B,A4,'💸 Transaction ซื้อ'!E:E),""),"-") -> 80 | G4: =IFERROR(IF(A4<>"",F4*B4,""),"-") -> 8400 | H4: 45437 | I4: 685 | J4: Deadstock | K4: =IF(A4<>"",IF(E4="InActive","-",SUMIFS('💰 Transaction ขาย'!E:E,'💰 Transaction ขาย'!B:B,A4,'💰 Transaction ขาย'!A:A,">"&'⚙️ Config'!$H$1-'⚙️ Config'!$H$2)),) -> 0 | L4: =IF(E4="InActive","-",IF(A4<>"",K4/'⚙️ Config'!$H$2,)) -> 0 | M4: =IF(E4="InActive","-",IF(L4<>"",(B4/L4)/30,)) -> #DIV/0! | N4: =IF(A4<>"", SUMIFS('💰 Transaction ขาย'!F:F,'💰 Transaction ขาย'!B:B,A4,'💰 Transaction ขาย'!A:A,">="&DATE(YEAR('⚙️ Config'!$H$1),1,1),'💰 Transaction ขาย'!A:A,"<="&DATE(YEAR('⚙️ Config'!$H$1),12,31)),) -> 0
A5: =IFERROR(__xludf.DUMMYFUNCTION("""COMPUTED_VALUE"""),"552 ชมพูเข้ม") -> 552 ชมพูเข้ม | B5: =IF(A5<>"",SUMIFS('💸 Transaction ซื้อ'!E:E,'💸 Transaction ซื้อ'!B:B,A5)-SUMIFS('💰 Transaction ขาย'!E:E,'💰 Transaction ขาย'!B:B,A5),"") -> 150 | C5: =IF(A5<>"",vlookup(A5,'📦 ชื่อสินค้า'!A:E,5,false),"") -> 5 | D5: =IF(A5<>"",VLOOKUP(A5,'📦 ชื่อสินค้า'!A:F,6,false),"") -> รุ่นสีอ่อน | E5: =IFERROR(IF(VLOOKUP(A5,'📦 ชื่อสินค้า'!A:G,7,false)="InActive","InActive",IF(A5<>"",IF(B5<=0,"สินค้าหมด",IF(B5<=C5,"ควรเติมทันที","OK")),"")),) -> OK | F5: =IFERROR(IF(A5<>"", SUMIF('💸 Transaction ซื้อ'!B:B,A5,'💸 Transaction ซื้อ'!G:G)/SUMIF('💸 Transaction ซื้อ'!B:B,A5,'💸 Transaction ซื้อ'!E:E),""),"-") -> 80 | G5: =IFERROR(IF(A5<>"",F5*B5,""),"-") -> 12000 | H5: 45430 | I5: 692 | J5: Deadstock | K5: =IF(A5<>"",IF(E5="InActive","-",SUMIFS('💰 Transaction ขาย'!E:E,'💰 Transaction ขาย'!B:B,A5,'💰 Transaction ขาย'!A:A,">"&'⚙️ Config'!$H$1-'⚙️ Config'!$H$2)),) -> 0 | L5: =IF(E5="InActive","-",IF(A5<>"",K5/'⚙️ Config'!$H$2,)) -> 0 | M5: =IF(E5="InActive","-",IF(L5<>"",(B5/L5)/30,)) -> #DIV/0! | N5: =IF(A5<>"", SUMIFS('💰 Transaction ขาย'!F:F,'💰 Transaction ขาย'!B:B,A5,'💰 Transaction ขาย'!A:A,">="&DATE(YEAR('⚙️ Config'!$H$1),1,1),'💰 Transaction ขาย'!A:A,"<="&DATE(YEAR('⚙️ Config'!$H$1),12,31)),) -> 0
A6: =IFERROR(__xludf.DUMMYFUNCTION("""COMPUTED_VALUE"""),"551 ชมพูอ่อน") -> 551 ชมพูอ่อน | B6: =IF(A6<>"",SUMIFS('💸 Transaction ซื้อ'!E:E,'💸 Transaction ซื้อ'!B:B,A6)-SUMIFS('💰 Transaction ขาย'!E:E,'💰 Transaction ขาย'!B:B,A6),"") -> 473 | C6: =IF(A6<>"",vlookup(A6,'📦 ชื่อสินค้า'!A:E,5,false),"") -> 5 | D6: =IF(A6<>"",VLOOKUP(A6,'📦 ชื่อสินค้า'!A:F,6,false),"") -> รุ่นสีอ่อน | E6: =IFERROR(IF(VLOOKUP(A6,'📦 ชื่อสินค้า'!A:G,7,false)="InActive","InActive",IF(A6<>"",IF(B6<=0,"สินค้าหมด",IF(B6<=C6,"ควรเติมทันที","OK")),"")),) -> OK | F6: =IFERROR(IF(A6<>"", SUMIF('💸 Transaction ซื้อ'!B:B,A6,'💸 Transaction ซื้อ'!G:G)/SUMIF('💸 Transaction ซื้อ'!B:B,A6,'💸 Transaction ซื้อ'!E:E),""),"-") -> 80 | G6: =IFERROR(IF(A6<>"",F6*B6,""),"-") -> 37840 | H6: - | I6: - | J6: - | K6: =IF(A6<>"",IF(E6="InActive","-",SUMIFS('💰 Transaction ขาย'!E:E,'💰 Transaction ขาย'!B:B,A6,'💰 Transaction ขาย'!A:A,">"&'⚙️ Config'!$H$1-'⚙️ Config'!$H$2)),) -> 0 | L6: =IF(E6="InActive","-",IF(A6<>"",K6/'⚙️ Config'!$H$2,)) -> 0 | M6: =IF(E6="InActive","-",IF(L6<>"",(B6/L6)/30,)) -> #DIV/0! | N6: =IF(A6<>"", SUMIFS('💰 Transaction ขาย'!F:F,'💰 Transaction ขาย'!B:B,A6,'💰 Transaction ขาย'!A:A,">="&DATE(YEAR('⚙️ Config'!$H$1),1,1),'💰 Transaction ขาย'!A:A,"<="&DATE(YEAR('⚙️ Config'!$H$1),12,31)),) -> 0
A7: =IFERROR(__xludf.DUMMYFUNCTION("""COMPUTED_VALUE"""),"860 ม่วงอ่อน") -> 860 ม่วงอ่อน | B7: =IF(A7<>"",SUMIFS('💸 Transaction ซื้อ'!E:E,'💸 Transaction ซื้อ'!B:B,A7)-SUMIFS('💰 Transaction ขาย'!E:E,'💰 Transaction ขาย'!B:B,A7),"") -> 188 | C7: =IF(A7<>"",vlookup(A7,'📦 ชื่อสินค้า'!A:E,5,false),"") -> 5 | D7: =IF(A7<>"",VLOOKUP(A7,'📦 ชื่อสินค้า'!A:F,6,false),"") -> รุ่นสีอ่อน | E7: =IFERROR(IF(VLOOKUP(A7,'📦 ชื่อสินค้า'!A:G,7,false)="InActive","InActive",IF(A7<>"",IF(B7<=0,"สินค้าหมด",IF(B7<=C7,"ควรเติมทันที","OK")),"")),) -> OK | F7: =IFERROR(IF(A7<>"", SUMIF('💸 Transaction ซื้อ'!B:B,A7,'💸 Transaction ซื้อ'!G:G)/SUMIF('💸 Transaction ซื้อ'!B:B,A7,'💸 Transaction ซื้อ'!E:E),""),"-") -> 80 | G7: =IFERROR(IF(A7<>"",F7*B7,""),"-") -> 15040 | H7: 45430 | I7: 692 | J7: Deadstock | K7: =IF(A7<>"",IF(E7="InActive","-",SUMIFS('💰 Transaction ขาย'!E:E,'💰 Transaction ขาย'!B:B,A7,'💰 Transaction ขาย'!A:A,">"&'⚙️ Config'!$H$1-'⚙️ Config'!$H$2)),) -> 0 | L7: =IF(E7="InActive","-",IF(A7<>"",K7/'⚙️ Config'!$H$2,)) -> 0 | M7: =IF(E7="InActive","-",IF(L7<>"",(B7/L7)/30,)) -> #DIV/0! | N7: =IF(A7<>"", SUMIFS('💰 Transaction ขาย'!F:F,'💰 Transaction ขาย'!B:B,A7,'💰 Transaction ขาย'!A:A,">="&DATE(YEAR('⚙️ Config'!$H$1),1,1),'💰 Transaction ขาย'!A:A,"<="&DATE(YEAR('⚙️ Config'!$H$1),12,31)),) -> 0
A8: =IFERROR(__xludf.DUMMYFUNCTION("""COMPUTED_VALUE"""),"591 เทาอ่อน") -> 591 เทาอ่อน | B8: =IF(A8<>"",SUMIFS('💸 Transaction ซื้อ'!E:E,'💸 Transaction ซื้อ'!B:B,A8)-SUMIFS('💰 Transaction ขาย'!E:E,'💰 Transaction ขาย'!B:B,A8),"") -> 130 | C8: =IF(A8<>"",vlookup(A8,'📦 ชื่อสินค้า'!A:E,5,false),"") -> 5 | D8: =IF(A8<>"",VLOOKUP(A8,'📦 ชื่อสินค้า'!A:F,6,false),"") -> รุ่นสีอ่อน | E8: =IFERROR(IF(VLOOKUP(A8,'📦 ชื่อสินค้า'!A:G,7,false)="InActive","InActive",IF(A8<>"",IF(B8<=0,"สินค้าหมด",IF(B8<=C8,"ควรเติมทันที","OK")),"")),) -> OK | F8: =IFERROR(IF(A8<>"", SUMIF('💸 Transaction ซื้อ'!B:B,A8,'💸 Transaction ซื้อ'!G:G)/SUMIF('💸 Transaction ซื้อ'!B:B,A8,'💸 Transaction ซื้อ'!E:E),""),"-") -> 70 | G8: =IFERROR(IF(A8<>"",F8*B8,""),"-") -> 9100 | H8: - | I8: - | J8: - | K8: =IF(A8<>"",IF(E8="InActive","-",SUMIFS('💰 Transaction ขาย'!E:E,'💰 Transaction ขาย'!B:B,A8,'💰 Transaction ขาย'!A:A,">"&'⚙️ Config'!$H$1-'⚙️ Config'!$H$2)),) -> 0 | L8: =IF(E8="InActive","-",IF(A8<>"",K8/'⚙️ Config'!$H$2,)) -> 0 | M8: =IF(E8="InActive","-",IF(L8<>"",(B8/L8)/30,)) -> #DIV/0! | N8: =IF(A8<>"", SUMIFS('💰 Transaction ขาย'!F:F,'💰 Transaction ขาย'!B:B,A8,'💰 Transaction ขาย'!A:A,">="&DATE(YEAR('⚙️ Config'!$H$1),1,1),'💰 Transaction ขาย'!A:A,"<="&DATE(YEAR('⚙️ Config'!$H$1),12,31)),) -> 0
A9: =IFERROR(__xludf.DUMMYFUNCTION("""COMPUTED_VALUE"""),"561 ฟ้าเข้ม") -> 561 ฟ้าเข้ม | B9: =IF(A9<>"",SUMIFS('💸 Transaction ซื้อ'!E:E,'💸 Transaction ซื้อ'!B:B,A9)-SUMIFS('💰 Transaction ขาย'!E:E,'💰 Transaction ขาย'!B:B,A9),"") -> 84 | C9: =IF(A9<>"",vlookup(A9,'📦 ชื่อสินค้า'!A:E,5,false),"") -> 5 | D9: =IF(A9<>"",VLOOKUP(A9,'📦 ชื่อสินค้า'!A:F,6,false),"") -> รุ่นสีอ่อน | E9: =IFERROR(IF(VLOOKUP(A9,'📦 ชื่อสินค้า'!A:G,7,false)="InActive","InActive",IF(A9<>"",IF(B9<=0,"สินค้าหมด",IF(B9<=C9,"ควรเติมทันที","OK")),"")),) -> OK | F9: =IFERROR(IF(A9<>"", SUMIF('💸 Transaction ซื้อ'!B:B,A9,'💸 Transaction ซื้อ'!G:G)/SUMIF('💸 Transaction ซื้อ'!B:B,A9,'💸 Transaction ซื้อ'!E:E),""),"-") -> 80 | G9: =IFERROR(IF(A9<>"",F9*B9,""),"-") -> 6720 | H9: 45430 | I9: 692 | J9: Deadstock | K9: =IF(A9<>"",IF(E9="InActive","-",SUMIFS('💰 Transaction ขาย'!E:E,'💰 Transaction ขาย'!B:B,A9,'💰 Transaction ขาย'!A:A,">"&'⚙️ Config'!$H$1-'⚙️ Config'!$H$2)),) -> 0 | L9: =IF(E9="InActive","-",IF(A9<>"",K9/'⚙️ Config'!$H$2,)) -> 0 | M9: =IF(E9="InActive","-",IF(L9<>"",(B9/L9)/30,)) -> #DIV/0! | N9: =IF(A9<>"", SUMIFS('💰 Transaction ขาย'!F:F,'💰 Transaction ขาย'!B:B,A9,'💰 Transaction ขาย'!A:A,">="&DATE(YEAR('⚙️ Config'!$H$1),1,1),'💰 Transaction ขาย'!A:A,"<="&DATE(YEAR('⚙️ Config'!$H$1),12,31)),) -> 0
A10: =IFERROR(__xludf.DUMMYFUNCTION("""COMPUTED_VALUE"""),"521 ครีม") -> 521 ครีม | B10: =IF(A10<>"",SUMIFS('💸 Transaction ซื้อ'!E:E,'💸 Transaction ซื้อ'!B:B,A10)-SUMIFS('💰 Transaction ขาย'!E:E,'💰 Transaction ขาย'!B:B,A10),"") -> 927 | C10: =IF(A10<>"",vlookup(A10,'📦 ชื่อสินค้า'!A:E,5,false),"") -> 10 | D10: =IF(A10<>"",VLOOKUP(A10,'📦 ชื่อสินค้า'!A:F,6,false),"") -> รุ่นสีอ่อน | E10: =IFERROR(IF(VLOOKUP(A10,'📦 ชื่อสินค้า'!A:G,7,false)="InActive","InActive",IF(A10<>"",IF(B10<=0,"สินค้าหมด",IF(B10<=C10,"ควรเติมทันที","OK")),"")),) -> OK | F10: =IFERROR(IF(A10<>"", SUMIF('💸 Transaction ซื้อ'!B:B,A10,'💸 Transaction ซื้อ'!G:G)/SUMIF('💸 Transaction ซื้อ'!B:B,A10,'💸 Transaction ซื้อ'!E:E),""),"-") -> 80 | G10: =IFERROR(IF(A10<>"",F10*B10,""),"-") -> 74160 | H10: 45430 | I10: 692 | J10: Deadstock | K10: =IF(A10<>"",IF(E10="InActive","-",SUMIFS('💰 Transaction ขาย'!E:E,'💰 Transaction ขาย'!B:B,A10,'💰 Transaction ขาย'!A:A,">"&'⚙️ Config'!$H$1-'⚙️ Config'!$H$2)),) -> 0 | L10: =IF(E10="InActive","-",IF(A10<>"",K10/'⚙️ Config'!$H$2,)) -> 0 | M10: =IF(E10="InActive","-",IF(L10<>"",(B10/L10)/30,)) -> #DIV/0! | N10: =IF(A10<>"", SUMIFS('💰 Transaction ขาย'!F:F,'💰 Transaction ขาย'!B:B,A10,'💰 Transaction ขาย'!A:A,">="&DATE(YEAR('⚙️ Config'!$H$1),1,1),'💰 Transaction ขาย'!A:A,"<="&DATE(YEAR('⚙️ Config'!$H$1),12,31)),) -> 0
A11: =IFERROR(__xludf.DUMMYFUNCTION("""COMPUTED_VALUE"""),"111 เงินเงา") -> 111 เงินเงา | B11: =IF(A11<>"",SUMIFS('💸 Transaction ซื้อ'!E:E,'💸 Transaction ซื้อ'!B:B,A11)-SUMIFS('💰 Transaction ขาย'!E:E,'💰 Transaction ขาย'!B:B,A11),"") -> 335 | C11: =IF(A11<>"",vlookup(A11,'📦 ชื่อสินค้า'!A:E,5,false),"") -> 50 | D11: =IF(A11<>"",VLOOKUP(A11,'📦 ชื่อสินค้า'!A:F,6,false),"") -> รุ่นสีพิเศษ A | E11: =IFERROR(IF(VLOOKUP(A11,'📦 ชื่อสินค้า'!A:G,7,false)="InActive","InActive",IF(A11<>"",IF(B11<=0,"สินค้าหมด",IF(B11<=C11,"ควรเติมทันที","OK")),"")),) -> OK | F11: =IFERROR(IF(A11<>"", SUMIF('💸 Transaction ซื้อ'!B:B,A11,'💸 Transaction ซื้อ'!G:G)/SUMIF('💸 Transaction ซื้อ'!B:B,A11,'💸 Transaction ซื้อ'!E:E),""),"-") -> 250 | G11: =IFERROR(IF(A11<>"",F11*B11,""),"-") -> 83750 | H11: - | I11: - | J11: - | K11: =IF(A11<>"",IF(E11="InActive","-",SUMIFS('💰 Transaction ขาย'!E:E,'💰 Transaction ขาย'!B:B,A11,'💰 Transaction ขาย'!A:A,">"&'⚙️ Config'!$H$1-'⚙️ Config'!$H$2)),) -> 0 | L11: =IF(E11="InActive","-",IF(A11<>"",K11/'⚙️ Config'!$H$2,)) -> 0 | M11: =IF(E11="InActive","-",IF(L11<>"",(B11/L11)/30,)) -> #DIV/0! | N11: =IF(A11<>"", SUMIFS('💰 Transaction ขาย'!F:F,'💰 Transaction ขาย'!B:B,A11,'💰 Transaction ขาย'!A:A,">="&DATE(YEAR('⚙️ Config'!$H$1),1,1),'💰 Transaction ขาย'!A:A,"<="&DATE(YEAR('⚙️ Config'!$H$1),12,31)),) -> 0
A12: =IFERROR(__xludf.DUMMYFUNCTION("""COMPUTED_VALUE"""),"112 เงินด้าน") -> 112 เงินด้าน | B12: =IF(A12<>"",SUMIFS('💸 Transaction ซื้อ'!E:E,'💸 Transaction ซื้อ'!B:B,A12)-SUMIFS('💰 Transaction ขาย'!E:E,'💰 Transaction ขาย'!B:B,A12),"") -> 335 | C12: =IF(A12<>"",vlookup(A12,'📦 ชื่อสินค้า'!A:E,5,false),"") -> 20 | D12: =IF(A12<>"",VLOOKUP(A12,'📦 ชื่อสินค้า'!A:F,6,false),"") -> รุ่นสีพิเศษ A | E12: =IFERROR(IF(VLOOKUP(A12,'📦 ชื่อสินค้า'!A:G,7,false)="InActive","InActive",IF(A12<>"",IF(B12<=0,"สินค้าหมด",IF(B12<=C12,"ควรเติมทันที","OK")),"")),) -> OK | F12: =IFERROR(IF(A12<>"", SUMIF('💸 Transaction ซื้อ'!B:B,A12,'💸 Transaction ซื้อ'!G:G)/SUMIF('💸 Transaction ซื้อ'!B:B,A12,'💸 Transaction ซื้อ'!E:E),""),"-") -> 250 | G12: =IFERROR(IF(A12<>"",F12*B12,""),"-") -> 83750 | H12: - | I12: - | J12: - | K12: =IF(A12<>"",IF(E12="InActive","-",SUMIFS('💰 Transaction ขาย'!E:E,'💰 Transaction ขาย'!B:B,A12,'💰 Transaction ขาย'!A:A,">"&'⚙️ Config'!$H$1-'⚙️ Config'!$H$2)),) -> 0 | L12: =IF(E12="InActive","-",IF(A12<>"",K12/'⚙️ Config'!$H$2,)) -> 0 | M12: =IF(E12="InActive","-",IF(L12<>"",(B12/L12)/30,)) -> #DIV/0! | N12: =IF(A12<>"", SUMIFS('💰 Transaction ขาย'!F:F,'💰 Transaction ขาย'!B:B,A12,'💰 Transaction ขาย'!A:A,">="&DATE(YEAR('⚙️ Config'!$H$1),1,1),'💰 Transaction ขาย'!A:A,"<="&DATE(YEAR('⚙️ Config'!$H$1),12,31)),) -> 0
A13: =IFERROR(__xludf.DUMMYFUNCTION("""COMPUTED_VALUE"""),"881 เปลือกไม้") -> 881 เปลือกไม้ | B13: =IF(A13<>"",SUMIFS('💸 Transaction ซื้อ'!E:E,'💸 Transaction ซื้อ'!B:B,A13)-SUMIFS('💰 Transaction ขาย'!E:E,'💰 Transaction ขาย'!B:B,A13),"") -> 414 | C13: =IF(A13<>"",vlookup(A13,'📦 ชื่อสินค้า'!A:E,5,false),"") -> 20 | D13: =IF(A13<>"",VLOOKUP(A13,'📦 ชื่อสินค้า'!A:F,6,false),"") -> รุ่นสีอ่อน | E13: =IFERROR(IF(VLOOKUP(A13,'📦 ชื่อสินค้า'!A:G,7,false)="InActive","InActive",IF(A13<>"",IF(B13<=0,"สินค้าหมด",IF(B13<=C13,"ควรเติมทันที","OK")),"")),) -> OK | F13: =IFERROR(IF(A13<>"", SUMIF('💸 Transaction ซื้อ'!B:B,A13,'💸 Transaction ซื้อ'!G:G)/SUMIF('💸 Transaction ซื้อ'!B:B,A13,'💸 Transaction ซื้อ'!E:E),""),"-") -> 80 | G13: =IFERROR(IF(A13<>"",F13*B13,""),"-") -> 33120 | H13: 45430 | I13: 692 | J13: Deadstock | K13: =IF(A13<>"",IF(E13="InActive","-",SUMIFS('💰 Transaction ขาย'!E:E,'💰 Transaction ขาย'!B:B,A13,'💰 Transaction ขาย'!A:A,">"&'⚙️ Config'!$H$1-'⚙️ Config'!$H$2)),) -> 0 | L13: =IF(E13="InActive","-",IF(A13<>"",K13/'⚙️ Config'!$H$2,)) -> 0 | M13: =IF(E13="InActive","-",IF(L13<>"",(B13/L13)/30,)) -> #DIV/0! | N13: =IF(A13<>"", SUMIFS('💰 Transaction ขาย'!F:F,'💰 Transaction ขาย'!B:B,A13,'💰 Transaction ขาย'!A:A,">="&DATE(YEAR('⚙️ Config'!$H$1),1,1),'💰 Transaction ขาย'!A:A,"<="&DATE(YEAR('⚙️ Config'!$H$1),12,31)),) -> 0
A14: =IFERROR(__xludf.DUMMYFUNCTION("""COMPUTED_VALUE"""),"863 ฟ้าพาสเทลเข้ม") -> 863 ฟ้าพาสเทลเข้ม | B14: =IF(A14<>"",SUMIFS('💸 Transaction ซื้อ'!E:E,'💸 Transaction ซื้อ'!B:B,A14)-SUMIFS('💰 Transaction ขาย'!E:E,'💰 Transaction ขาย'!B:B,A14),"") -> 68 | C14: =IF(A14<>"",vlookup(A14,'📦 ชื่อสินค้า'!A:E,5,false),"") -> 81 | D14: =IF(A14<>"",VLOOKUP(A14,'📦 ชื่อสินค้า'!A:F,6,false),"") -> รุ่นสีอ่อน | E14: =IFERROR(IF(VLOOKUP(A14,'📦 ชื่อสินค้า'!A:G,7,false)="InActive","InActive",IF(A14<>"",IF(B14<=0,"สินค้าหมด",IF(B14<=C14,"ควรเติมทันที","OK")),"")),) -> ควรเติมทันที | F14: =IFERROR(IF(A14<>"", SUMIF('💸 Transaction ซื้อ'!B:B,A14,'💸 Transaction ซื้อ'!G:G)/SUMIF('💸 Transaction ซื้อ'!B:B,A14,'💸 Transaction ซื้อ'!E:E),""),"-") -> 80 | G14: =IFERROR(IF(A14<>"",F14*B14,""),"-") -> 5440 | H14: - | I14: - | J14: - | K14: =IF(A14<>"",IF(E14="InActive","-",SUMIFS('💰 Transaction ขาย'!E:E,'💰 Transaction ขาย'!B:B,A14,'💰 Transaction ขาย'!A:A,">"&'⚙️ Config'!$H$1-'⚙️ Config'!$H$2)),) -> 0 | L14: =IF(E14="InActive","-",IF(A14<>"",K14/'⚙️ Config'!$H$2,)) -> 0 | M14: =IF(E14="InActive","-",IF(L14<>"",(B14/L14)/30,)) -> #DIV/0! | N14: =IF(A14<>"", SUMIFS('💰 Transaction ขาย'!F:F,'💰 Transaction ขาย'!B:B,A14,'💰 Transaction ขาย'!A:A,">="&DATE(YEAR('⚙️ Config'!$H$1),1,1),'💰 Transaction ขาย'!A:A,"<="&DATE(YEAR('⚙️ Config'!$H$1),12,31)),) -> 0
A15: =IFERROR(__xludf.DUMMYFUNCTION("""COMPUTED_VALUE"""),"881 เปลือกไม้ รุ่นหยัก") -> 881 เปลือกไม้ รุ่นหยัก | B15: =IF(A15<>"",SUMIFS('💸 Transaction ซื้อ'!E:E,'💸 Transaction ซื้อ'!B:B,A15)-SUMIFS('💰 Transaction ขาย'!E:E,'💰 Transaction ขาย'!B:B,A15),"") -> -1 | C15: =IF(A15<>"",vlookup(A15,'📦 ชื่อสินค้า'!A:E,5,false),"") -> 5 | D15: =IF(A15<>"",VLOOKUP(A15,'📦 ชื่อสินค้า'!A:F,6,false),"") -> รุ่นหยัก | E15: =IFERROR(IF(VLOOKUP(A15,'📦 ชื่อสินค้า'!A:G,7,false)="InActive","InActive",IF(A15<>"",IF(B15<=0,"สินค้าหมด",IF(B15<=C15,"ควรเติมทันที","OK")),"")),) -> สินค้าหมด | F15: =IFERROR(IF(A15<>"", SUMIF('💸 Transaction ซื้อ'!B:B,A15,'💸 Transaction ซื้อ'!G:G)/SUMIF('💸 Transaction ซื้อ'!B:B,A15,'💸 Transaction ซื้อ'!E:E),""),"-") -> - | G15: =IFERROR(IF(A15<>"",F15*B15,""),"-") -> - | H15: 45411 | I15: 711 | J15: Deadstock | K15: =IF(A15<>"",IF(E15="InActive","-",SUMIFS('💰 Transaction ขาย'!E:E,'💰 Transaction ขาย'!B:B,A15,'💰 Transaction ขาย'!A:A,">"&'⚙️ Config'!$H$1-'⚙️ Config'!$H$2)),) -> 0 | L15: =IF(E15="InActive","-",IF(A15<>"",K15/'⚙️ Config'!$H$2,)) -> 0 | M15: =IF(E15="InActive","-",IF(L15<>"",(B15/L15)/30,)) -> #DIV/0! | N15: =IF(A15<>"", SUMIFS('💰 Transaction ขาย'!F:F,'💰 Transaction ขาย'!B:B,A15,'💰 Transaction ขาย'!A:A,">="&DATE(YEAR('⚙️ Config'!$H$1),1,1),'💰 Transaction ขาย'!A:A,"<="&DATE(YEAR('⚙️ Config'!$H$1),12,31)),) -> 0
A16: =IFERROR(__xludf.DUMMYFUNCTION("""COMPUTED_VALUE"""),"853 ชมพูพาสเทล") -> 853 ชมพูพาสเทล | B16: =IF(A16<>"",SUMIFS('💸 Transaction ซื้อ'!E:E,'💸 Transaction ซื้อ'!B:B,A16)-SUMIFS('💰 Transaction ขาย'!E:E,'💰 Transaction ขาย'!B:B,A16),"") -> -11 | C16: =IF(A16<>"",vlookup(A16,'📦 ชื่อสินค้า'!A:E,5,false),"") -> 5 | D16: =IF(A16<>"",VLOOKUP(A16,'📦 ชื่อสินค้า'!A:F,6,false),"") -> รุ่นสีอ่อน | E16: =IFERROR(IF(VLOOKUP(A16,'📦 ชื่อสินค้า'!A:G,7,false)="InActive","InActive",IF(A16<>"",IF(B16<=0,"สินค้าหมด",IF(B16<=C16,"ควรเติมทันที","OK")),"")),) -> สินค้าหมด | F16: =IFERROR(IF(A16<>"", SUMIF('💸 Transaction ซื้อ'!B:B,A16,'💸 Transaction ซื้อ'!G:G)/SUMIF('💸 Transaction ซื้อ'!B:B,A16,'💸 Transaction ซื้อ'!E:E),""),"-") -> - | G16: =IFERROR(IF(A16<>"",F16*B16,""),"-") -> - | H16: 45430 | I16: 692 | J16: Deadstock | K16: =IF(A16<>"",IF(E16="InActive","-",SUMIFS('💰 Transaction ขาย'!E:E,'💰 Transaction ขาย'!B:B,A16,'💰 Transaction ขาย'!A:A,">"&'⚙️ Config'!$H$1-'⚙️ Config'!$H$2)),) -> 0 | L16: =IF(E16="InActive","-",IF(A16<>"",K16/'⚙️ Config'!$H$2,)) -> 0 | M16: =IF(E16="InActive","-",IF(L16<>"",(B16/L16)/30,)) -> #DIV/0! | N16: =IF(A16<>"", SUMIFS('💰 Transaction ขาย'!F:F,'💰 Transaction ขาย'!B:B,A16,'💰 Transaction ขาย'!A:A,">="&DATE(YEAR('⚙️ Config'!$H$1),1,1),'💰 Transaction ขาย'!A:A,"<="&DATE(YEAR('⚙️ Config'!$H$1),12,31)),) -> 0
A17: =IFERROR(__xludf.DUMMYFUNCTION("""COMPUTED_VALUE"""),"862 ฟ้า PT อ่อน") -> 862 ฟ้า PT อ่อน | B17: =IF(A17<>"",SUMIFS('💸 Transaction ซื้อ'!E:E,'💸 Transaction ซื้อ'!B:B,A17)-SUMIFS('💰 Transaction ขาย'!E:E,'💰 Transaction ขาย'!B:B,A17),"") -> -14 | C17: =IF(A17<>"",vlookup(A17,'📦 ชื่อสินค้า'!A:E,5,false),"") -> 5 | D17: =IF(A17<>"",VLOOKUP(A17,'📦 ชื่อสินค้า'!A:F,6,false),"") -> รุ่นสีอ่อน | E17: =IFERROR(IF(VLOOKUP(A17,'📦 ชื่อสินค้า'!A:G,7,false)="InActive","InActive",IF(A17<>"",IF(B17<=0,"สินค้าหมด",IF(B17<=C17,"ควรเติมทันที","OK")),"")),) -> สินค้าหมด | F17: =IFERROR(IF(A17<>"", SUMIF('💸 Transaction ซื้อ'!B:B,A17,'💸 Transaction ซื้อ'!G:G)/SUMIF('💸 Transaction ซื้อ'!B:B,A17,'💸 Transaction ซื้อ'!E:E),""),"-") -> - | G17: =IFERROR(IF(A17<>"",F17*B17,""),"-") -> - | H17: 45430 | I17: 692 | J17: Deadstock | K17: =IF(A17<>"",IF(E17="InActive","-",SUMIFS('💰 Transaction ขาย'!E:E,'💰 Transaction ขาย'!B:B,A17,'💰 Transaction ขาย'!A:A,">"&'⚙️ Config'!$H$1-'⚙️ Config'!$H$2)),) -> 0 | L17: =IF(E17="InActive","-",IF(A17<>"",K17/'⚙️ Config'!$H$2,)) -> 0 | M17: =IF(E17="InActive","-",IF(L17<>"",(B17/L17)/30,)) -> #DIV/0! | N17: =IF(A17<>"", SUMIFS('💰 Transaction ขาย'!F:F,'💰 Transaction ขาย'!B:B,A17,'💰 Transaction ขาย'!A:A,">="&DATE(YEAR('⚙️ Config'!$H$1),1,1),'💰 Transaction ขาย'!A:A,"<="&DATE(YEAR('⚙️ Config'!$H$1),12,31)),) -> 0
A18: =IFERROR(__xludf.DUMMYFUNCTION("""COMPUTED_VALUE"""),"863 ฟ้า PT เข้ม") -> 863 ฟ้า PT เข้ม | B18: =IF(A18<>"",SUMIFS('💸 Transaction ซื้อ'!E:E,'💸 Transaction ซื้อ'!B:B,A18)-SUMIFS('💰 Transaction ขาย'!E:E,'💰 Transaction ขาย'!B:B,A18),"") -> 0 | C18: =IF(A18<>"",vlookup(A18,'📦 ชื่อสินค้า'!A:E,5,false),"") -> 5 | D18: =IF(A18<>"",VLOOKUP(A18,'📦 ชื่อสินค้า'!A:F,6,false),"") -> รุ่นสีอ่อน | E18: =IFERROR(IF(VLOOKUP(A18,'📦 ชื่อสินค้า'!A:G,7,false)="InActive","InActive",IF(A18<>"",IF(B18<=0,"สินค้าหมด",IF(B18<=C18,"ควรเติมทันที","OK")),"")),) -> สินค้าหมด | F18: =IFERROR(IF(A18<>"", SUMIF('💸 Transaction ซื้อ'!B:B,A18,'💸 Transaction ซื้อ'!G:G)/SUMIF('💸 Transaction ซื้อ'!B:B,A18,'💸 Transaction ซื้อ'!E:E),""),"-") -> - | G18: =IFERROR(IF(A18<>"",F18*B18,""),"-") -> - | H18: - | I18: - | J18: - | K18: =IF(A18<>"",IF(E18="InActive","-",SUMIFS('💰 Transaction ขาย'!E:E,'💰 Transaction ขาย'!B:B,A18,'💰 Transaction ขาย'!A:A,">"&'⚙️ Config'!$H$1-'⚙️ Config'!$H$2)),) -> 0 | L18: =IF(E18="InActive","-",IF(A18<>"",K18/'⚙️ Config'!$H$2,)) -> 0 | M18: =IF(E18="InActive","-",IF(L18<>"",(B18/L18)/30,)) -> #DIV/0! | N18: =IF(A18<>"", SUMIFS('💰 Transaction ขาย'!F:F,'💰 Transaction ขาย'!B:B,A18,'💰 Transaction ขาย'!A:A,">="&DATE(YEAR('⚙️ Config'!$H$1),1,1),'💰 Transaction ขาย'!A:A,"<="&DATE(YEAR('⚙️ Config'!$H$1),12,31)),) -> 0
A19: =IFERROR(__xludf.DUMMYFUNCTION("""COMPUTED_VALUE"""),"522 เหลืองอ่อน") -> 522 เหลืองอ่อน | B19: =IF(A19<>"",SUMIFS('💸 Transaction ซื้อ'!E:E,'💸 Transaction ซื้อ'!B:B,A19)-SUMIFS('💰 Transaction ขาย'!E:E,'💰 Transaction ขาย'!B:B,A19),"") -> -10 | C19: =IF(A19<>"",vlookup(A19,'📦 ชื่อสินค้า'!A:E,5,false),"") -> 5 | D19: =IF(A19<>"",VLOOKUP(A19,'📦 ชื่อสินค้า'!A:F,6,false),"") -> รุ่นสีอ่อน | E19: =IFERROR(IF(VLOOKUP(A19,'📦 ชื่อสินค้า'!A:G,7,false)="InActive","InActive",IF(A19<>"",IF(B19<=0,"สินค้าหมด",IF(B19<=C19,"ควรเติมทันที","OK")),"")),) -> สินค้าหมด | F19: =IFERROR(IF(A19<>"", SUMIF('💸 Transaction ซื้อ'!B:B,A19,'💸 Transaction ซื้อ'!G:G)/SUMIF('💸 Transaction ซื้อ'!B:B,A19,'💸 Transaction ซื้อ'!E:E),""),"-") -> - | G19: =IFERROR(IF(A19<>"",F19*B19,""),"-") -> - | H19: 45430 | I19: 692 | J19: Deadstock | K19: =IF(A19<>"",IF(E19="InActive","-",SUMIFS('💰 Transaction ขาย'!E:E,'💰 Transaction ขาย'!B:B,A19,'💰 Transaction ขาย'!A:A,">"&'⚙️ Config'!$H$1-'⚙️ Config'!$H$2)),) -> 0 | L19: =IF(E19="InActive","-",IF(A19<>"",K19/'⚙️ Config'!$H$2,)) -> 0 | M19: =IF(E19="InActive","-",IF(L19<>"",(B19/L19)/30,)) -> #DIV/0! | N19: =IF(A19<>"", SUMIFS('💰 Transaction ขาย'!F:F,'💰 Transaction ขาย'!B:B,A19,'💰 Transaction ขาย'!A:A,">="&DATE(YEAR('⚙️ Config'!$H$1),1,1),'💰 Transaction ขาย'!A:A,"<="&DATE(YEAR('⚙️ Config'!$H$1),12,31)),) -> 0
A20: =IFERROR(__xludf.DUMMYFUNCTION("""COMPUTED_VALUE"""),"571 เขียวหยก") -> 571 เขียวหยก | B20: =IF(A20<>"",SUMIFS('💸 Transaction ซื้อ'!E:E,'💸 Transaction ซื้อ'!B:B,A20)-SUMIFS('💰 Transaction ขาย'!E:E,'💰 Transaction ขาย'!B:B,A20),"") -> -10 | C20: =IF(A20<>"",vlookup(A20,'📦 ชื่อสินค้า'!A:E,5,false),"") -> 5 | D20: =IF(A20<>"",VLOOKUP(A20,'📦 ชื่อสินค้า'!A:F,6,false),"") -> รุ่นสีอ่อน | E20: =IFERROR(IF(VLOOKUP(A20,'📦 ชื่อสินค้า'!A:G,7,false)="InActive","InActive",IF(A20<>"",IF(B20<=0,"สินค้าหมด",IF(B20<=C20,"ควรเติมทันที","OK")),"")),) -> สินค้าหมด | F20: =IFERROR(IF(A20<>"", SUMIF('💸 Transaction ซื้อ'!B:B,A20,'💸 Transaction ซื้อ'!G:G)/SUMIF('💸 Transaction ซื้อ'!B:B,A20,'💸 Transaction ซื้อ'!E:E),""),"-") -> - | G20: =IFERROR(IF(A20<>"",F20*B20,""),"-") -> - | H20: 45430 | I20: 692 | J20: Deadstock | K20: =IF(A20<>"",IF(E20="InActive","-",SUMIFS('💰 Transaction ขาย'!E:E,'💰 Transaction ขาย'!B:B,A20,'💰 Transaction ขาย'!A:A,">"&'⚙️ Config'!$H$1-'⚙️ Config'!$H$2)),) -> 0 | L20: =IF(E20="InActive","-",IF(A20<>"",K20/'⚙️ Config'!$H$2,)) -> 0 | M20: =IF(E20="InActive","-",IF(L20<>"",(B20/L20)/30,)) -> #DIV/0! | N20: =IF(A20<>"", SUMIFS('💰 Transaction ขาย'!F:F,'💰 Transaction ขาย'!B:B,A20,'💰 Transaction ขาย'!A:A,">="&DATE(YEAR('⚙️ Config'!$H$1),1,1),'💰 Transaction ขาย'!A:A,"<="&DATE(YEAR('⚙️ Config'!$H$1),12,31)),) -> 0
A21: =IFERROR(__xludf.DUMMYFUNCTION("""COMPUTED_VALUE"""),"882 กาแฟ") -> 882 กาแฟ | B21: =IF(A21<>"",SUMIFS('💸 Transaction ซื้อ'!E:E,'💸 Transaction ซื้อ'!B:B,A21)-SUMIFS('💰 Transaction ขาย'!E:E,'💰 Transaction ขาย'!B:B,A21),"") -> -10 | C21: =IF(A21<>"",vlookup(A21,'📦 ชื่อสินค้า'!A:E,5,false),"") -> 5 | D21: =IF(A21<>"",VLOOKUP(A21,'📦 ชื่อสินค้า'!A:F,6,false),"") -> รุ่นสีอ่อน | E21: =IFERROR(IF(VLOOKUP(A21,'📦 ชื่อสินค้า'!A:G,7,false)="InActive","InActive",IF(A21<>"",IF(B21<=0,"สินค้าหมด",IF(B21<=C21,"ควรเติมทันที","OK")),"")),) -> สินค้าหมด | F21: =IFERROR(IF(A21<>"", SUMIF('💸 Transaction ซื้อ'!B:B,A21,'💸 Transaction ซื้อ'!G:G)/SUMIF('💸 Transaction ซื้อ'!B:B,A21,'💸 Transaction ซื้อ'!E:E),""),"-") -> - | G21: =IFERROR(IF(A21<>"",F21*B21,""),"-") -> - | H21: 45430 | I21: 692 | J21: Deadstock | K21: =IF(A21<>"",IF(E21="InActive","-",SUMIFS('💰 Transaction ขาย'!E:E,'💰 Transaction ขาย'!B:B,A21,'💰 Transaction ขาย'!A:A,">"&'⚙️ Config'!$H$1-'⚙️ Config'!$H$2)),) -> 0 | L21: =IF(E21="InActive","-",IF(A21<>"",K21/'⚙️ Config'!$H$2,)) -> 0 | M21: =IF(E21="InActive","-",IF(L21<>"",(B21/L21)/30,)) -> #DIV/0! | N21: =IF(A21<>"", SUMIFS('💰 Transaction ขาย'!F:F,'💰 Transaction ขาย'!B:B,A21,'💰 Transaction ขาย'!A:A,">="&DATE(YEAR('⚙️ Config'!$H$1),1,1),'💰 Transaction ขาย'!A:A,"<="&DATE(YEAR('⚙️ Config'!$H$1),12,31)),) -> 0
A22: =IFERROR(__xludf.DUMMYFUNCTION("""COMPUTED_VALUE"""),"511 กรีนรีด") -> 511 กรีนรีด | B22: =IF(A22<>"",SUMIFS('💸 Transaction ซื้อ'!E:E,'💸 Transaction ซื้อ'!B:B,A22)-SUMIFS('💰 Transaction ขาย'!E:E,'💰 Transaction ขาย'!B:B,A22),"") -> 0 | C22: =IF(A22<>"",vlookup(A22,'📦 ชื่อสินค้า'!A:E,5,false),"") -> 5 | D22: =IF(A22<>"",VLOOKUP(A22,'📦 ชื่อสินค้า'!A:F,6,false),"") -> รุ่นสีอ่อน | E22: =IFERROR(IF(VLOOKUP(A22,'📦 ชื่อสินค้า'!A:G,7,false)="InActive","InActive",IF(A22<>"",IF(B22<=0,"สินค้าหมด",IF(B22<=C22,"ควรเติมทันที","OK")),"")),) -> สินค้าหมด | F22: =IFERROR(IF(A22<>"", SUMIF('💸 Transaction ซื้อ'!B:B,A22,'💸 Transaction ซื้อ'!G:G)/SUMIF('💸 Transaction ซื้อ'!B:B,A22,'💸 Transaction ซื้อ'!E:E),""),"-") -> - | G22: =IFERROR(IF(A22<>"",F22*B22,""),"-") -> - | H22: - | I22: - | J22: - | K22: =IF(A22<>"",IF(E22="InActive","-",SUMIFS('💰 Transaction ขาย'!E:E,'💰 Transaction ขาย'!B:B,A22,'💰 Transaction ขาย'!A:A,">"&'⚙️ Config'!$H$1-'⚙️ Config'!$H$2)),) -> 0 | L22: =IF(E22="InActive","-",IF(A22<>"",K22/'⚙️ Config'!$H$2,)) -> 0 | M22: =IF(E22="InActive","-",IF(L22<>"",(B22/L22)/30,)) -> #DIV/0! | N22: =IF(A22<>"", SUMIFS('💰 Transaction ขาย'!F:F,'💰 Transaction ขาย'!B:B,A22,'💰 Transaction ขาย'!A:A,">="&DATE(YEAR('⚙️ Config'!$H$1),1,1),'💰 Transaction ขาย'!A:A,"<="&DATE(YEAR('⚙️ Config'!$H$1),12,31)),) -> 0
B23: =IF(A23<>"",SUMIFS('💸 Transaction ซื้อ'!E:E,'💸 Transaction ซื้อ'!B:B,A23)-SUMIFS('💰 Transaction ขาย'!E:E,'💰 Transaction ขาย'!B:B,A23),"") | C23: =IF(A23<>"",vlookup(A23,'📦 ชื่อสินค้า'!A:E,5,false),"") | D23: =IF(A23<>"",VLOOKUP(A23,'📦 ชื่อสินค้า'!A:F,6,false),"") | E23: =IFERROR(IF(VLOOKUP(A23,'📦 ชื่อสินค้า'!A:G,7,false)="InActive","InActive",IF(A23<>"",IF(B23<=0,"สินค้าหมด",IF(B23<=C23,"ควรเติมทันที","OK")),"")),) | F23: =IFERROR(IF(A23<>"", SUMIF('💸 Transaction ซื้อ'!B:B,A23,'💸 Transaction ซื้อ'!G:G)/SUMIF('💸 Transaction ซื้อ'!B:B,A23,'💸 Transaction ซื้อ'!E:E),""),"-") | G23: =IFERROR(IF(A23<>"",F23*B23,""),"-") | K23: =IF(A23<>"",IF(E23="InActive","-",SUMIFS('💰 Transaction ขาย'!E:E,'💰 Transaction ขาย'!B:B,A23,'💰 Transaction ขาย'!A:A,">"&'⚙️ Config'!$H$1-'⚙️ Config'!$H$2)),) | L23: =IF(E23="InActive","-",IF(A23<>"",K23/'⚙️ Config'!$H$2,)) | M23: =IF(E23="InActive","-",IF(L23<>"",(B23/L23)/30,)) | N23: =IF(A23<>"", SUMIFS('💰 Transaction ขาย'!F:F,'💰 Transaction ขาย'!B:B,A23,'💰 Transaction ขาย'!A:A,">="&DATE(YEAR('⚙️ Config'!$H$1),1,1),'💰 Transaction ขาย'!A:A,"<="&DATE(YEAR('⚙️ Config'!$H$1),12,31)),)
B24: =IF(A24<>"",SUMIFS('💸 Transaction ซื้อ'!E:E,'💸 Transaction ซื้อ'!B:B,A24)-SUMIFS('💰 Transaction ขาย'!E:E,'💰 Transaction ขาย'!B:B,A24),"") | C24: =IF(A24<>"",vlookup(A24,'📦 ชื่อสินค้า'!A:E,5,false),"") | D24: =IF(A24<>"",VLOOKUP(A24,'📦 ชื่อสินค้า'!A:F,6,false),"") | E24: =IFERROR(IF(VLOOKUP(A24,'📦 ชื่อสินค้า'!A:G,7,false)="InActive","InActive",IF(A24<>"",IF(B24<=0,"สินค้าหมด",IF(B24<=C24,"ควรเติมทันที","OK")),"")),) | F24: =IFERROR(IF(A24<>"", SUMIF('💸 Transaction ซื้อ'!B:B,A24,'💸 Transaction ซื้อ'!G:G)/SUMIF('💸 Transaction ซื้อ'!B:B,A24,'💸 Transaction ซื้อ'!E:E),""),"-") | G24: =IFERROR(IF(A24<>"",F24*B24,""),"-") | K24: =IF(A24<>"",IF(E24="InActive","-",SUMIFS('💰 Transaction ขาย'!E:E,'💰 Transaction ขาย'!B:B,A24,'💰 Transaction ขาย'!A:A,">"&'⚙️ Config'!$H$1-'⚙️ Config'!$H$2)),) | L24: =IF(E24="InActive","-",IF(A24<>"",K24/'⚙️ Config'!$H$2,)) | M24: =IF(E24="InActive","-",IF(L24<>"",(B24/L24)/30,)) | N24: =IF(A24<>"", SUMIFS('💰 Transaction ขาย'!F:F,'💰 Transaction ขาย'!B:B,A24,'💰 Transaction ขาย'!A:A,">="&DATE(YEAR('⚙️ Config'!$H$1),1,1),'💰 Transaction ขาย'!A:A,"<="&DATE(YEAR('⚙️ Config'!$H$1),12,31)),)
B25: =IF(A25<>"",SUMIFS('💸 Transaction ซื้อ'!E:E,'💸 Transaction ซื้อ'!B:B,A25)-SUMIFS('💰 Transaction ขาย'!E:E,'💰 Transaction ขาย'!B:B,A25),"") | C25: =IF(A25<>"",vlookup(A25,'📦 ชื่อสินค้า'!A:E,5,false),"") | D25: =IF(A25<>"",VLOOKUP(A25,'📦 ชื่อสินค้า'!A:F,6,false),"") | E25: =IFERROR(IF(VLOOKUP(A25,'📦 ชื่อสินค้า'!A:G,7,false)="InActive","InActive",IF(A25<>"",IF(B25<=0,"สินค้าหมด",IF(B25<=C25,"ควรเติมทันที","OK")),"")),) | F25: =IFERROR(IF(A25<>"", SUMIF('💸 Transaction ซื้อ'!B:B,A25,'💸 Transaction ซื้อ'!G:G)/SUMIF('💸 Transaction ซื้อ'!B:B,A25,'💸 Transaction ซื้อ'!E:E),""),"-") | G25: =IFERROR(IF(A25<>"",F25*B25,""),"-") | K25: =IF(A25<>"",IF(E25="InActive","-",SUMIFS('💰 Transaction ขาย'!E:E,'💰 Transaction ขาย'!B:B,A25,'💰 Transaction ขาย'!A:A,">"&'⚙️ Config'!$H$1-'⚙️ Config'!$H$2)),) | L25: =IF(E25="InActive","-",IF(A25<>"",K25/'⚙️ Config'!$H$2,)) | M25: =IF(E25="InActive","-",IF(L25<>"",(B25/L25)/30,)) | N25: =IF(A25<>"", SUMIFS('💰 Transaction ขาย'!F:F,'💰 Transaction ขาย'!B:B,A25,'💰 Transaction ขาย'!A:A,">="&DATE(YEAR('⚙️ Config'!$H$1),1,1),'💰 Transaction ขาย'!A:A,"<="&DATE(YEAR('⚙️ Config'!$H$1),12,31)),)
B26: =IF(A26<>"",SUMIFS('💸 Transaction ซื้อ'!E:E,'💸 Transaction ซื้อ'!B:B,A26)-SUMIFS('💰 Transaction ขาย'!E:E,'💰 Transaction ขาย'!B:B,A26),"") | C26: =IF(A26<>"",vlookup(A26,'📦 ชื่อสินค้า'!A:E,5,false),"") | D26: =IF(A26<>"",VLOOKUP(A26,'📦 ชื่อสินค้า'!A:F,6,false),"") | E26: =IFERROR(IF(VLOOKUP(A26,'📦 ชื่อสินค้า'!A:G,7,false)="InActive","InActive",IF(A26<>"",IF(B26<=0,"สินค้าหมด",IF(B26<=C26,"ควรเติมทันที","OK")),"")),) | F26: =IFERROR(IF(A26<>"", SUMIF('💸 Transaction ซื้อ'!B:B,A26,'💸 Transaction ซื้อ'!G:G)/SUMIF('💸 Transaction ซื้อ'!B:B,A26,'💸 Transaction ซื้อ'!E:E),""),"-") | G26: =IFERROR(IF(A26<>"",F26*B26,""),"-") | K26: =IF(A26<>"",IF(E26="InActive","-",SUMIFS('💰 Transaction ขาย'!E:E,'💰 Transaction ขาย'!B:B,A26,'💰 Transaction ขาย'!A:A,">"&'⚙️ Config'!$H$1-'⚙️ Config'!$H$2)),) | L26: =IF(E26="InActive","-",IF(A26<>"",K26/'⚙️ Config'!$H$2,)) | M26: =IF(E26="InActive","-",IF(L26<>"",(B26/L26)/30,)) | N26: =IF(A26<>"", SUMIFS('💰 Transaction ขาย'!F:F,'💰 Transaction ขาย'!B:B,A26,'💰 Transaction ขาย'!A:A,">="&DATE(YEAR('⚙️ Config'!$H$1),1,1),'💰 Transaction ขาย'!A:A,"<="&DATE(YEAR('⚙️ Config'!$H$1),12,31)),)
B27: =IF(A27<>"",SUMIFS('💸 Transaction ซื้อ'!E:E,'💸 Transaction ซื้อ'!B:B,A27)-SUMIFS('💰 Transaction ขาย'!E:E,'💰 Transaction ขาย'!B:B,A27),"") | C27: =IF(A27<>"",vlookup(A27,'📦 ชื่อสินค้า'!A:E,5,false),"") | D27: =IF(A27<>"",VLOOKUP(A27,'📦 ชื่อสินค้า'!A:F,6,false),"") | E27: =IFERROR(IF(VLOOKUP(A27,'📦 ชื่อสินค้า'!A:G,7,false)="InActive","InActive",IF(A27<>"",IF(B27<=0,"สินค้าหมด",IF(B27<=C27,"ควรเติมทันที","OK")),"")),) | F27: =IFERROR(IF(A27<>"", SUMIF('💸 Transaction ซื้อ'!B:B,A27,'💸 Transaction ซื้อ'!G:G)/SUMIF('💸 Transaction ซื้อ'!B:B,A27,'💸 Transaction ซื้อ'!E:E),""),"-") | G27: =IFERROR(IF(A27<>"",F27*B27,""),"-") | K27: =IF(A27<>"",IF(E27="InActive","-",SUMIFS('💰 Transaction ขาย'!E:E,'💰 Transaction ขาย'!B:B,A27,'💰 Transaction ขาย'!A:A,">"&'⚙️ Config'!$H$1-'⚙️ Config'!$H$2)),) | L27: =IF(E27="InActive","-",IF(A27<>"",K27/'⚙️ Config'!$H$2,)) | M27: =IF(E27="InActive","-",IF(L27<>"",(B27/L27)/30,)) | N27: =IF(A27<>"", SUMIFS('💰 Transaction ขาย'!F:F,'💰 Transaction ขาย'!B:B,A27,'💰 Transaction ขาย'!A:A,">="&DATE(YEAR('⚙️ Config'!$H$1),1,1),'💰 Transaction ขาย'!A:A,"<="&DATE(YEAR('⚙️ Config'!$H$1),12,31)),)
B28: =IF(A28<>"",SUMIFS('💸 Transaction ซื้อ'!E:E,'💸 Transaction ซื้อ'!B:B,A28)-SUMIFS('💰 Transaction ขาย'!E:E,'💰 Transaction ขาย'!B:B,A28),"") | C28: =IF(A28<>"",vlookup(A28,'📦 ชื่อสินค้า'!A:E,5,false),"") | D28: =IF(A28<>"",VLOOKUP(A28,'📦 ชื่อสินค้า'!A:F,6,false),"") | E28: =IFERROR(IF(VLOOKUP(A28,'📦 ชื่อสินค้า'!A:G,7,false)="InActive","InActive",IF(A28<>"",IF(B28<=0,"สินค้าหมด",IF(B28<=C28,"ควรเติมทันที","OK")),"")),) | F28: =IFERROR(IF(A28<>"", SUMIF('💸 Transaction ซื้อ'!B:B,A28,'💸 Transaction ซื้อ'!G:G)/SUMIF('💸 Transaction ซื้อ'!B:B,A28,'💸 Transaction ซื้อ'!E:E),""),"-") | G28: =IFERROR(IF(A28<>"",F28*B28,""),"-") | K28: =IF(A28<>"",IF(E28="InActive","-",SUMIFS('💰 Transaction ขาย'!E:E,'💰 Transaction ขาย'!B:B,A28,'💰 Transaction ขาย'!A:A,">"&'⚙️ Config'!$H$1-'⚙️ Config'!$H$2)),) | L28: =IF(E28="InActive","-",IF(A28<>"",K28/'⚙️ Config'!$H$2,)) | M28: =IF(E28="InActive","-",IF(L28<>"",(B28/L28)/30,)) | N28: =IF(A28<>"", SUMIFS('💰 Transaction ขาย'!F:F,'💰 Transaction ขาย'!B:B,A28,'💰 Transaction ขาย'!A:A,">="&DATE(YEAR('⚙️ Config'!$H$1),1,1),'💰 Transaction ขาย'!A:A,"<="&DATE(YEAR('⚙️ Config'!$H$1),12,31)),)
